Workbook

Sheet DASHBOARD
B1: ▸ IRS EURO TRADING DESK · RISK DASHBOARD
B2: €STR OIS & EURIBOR 6M | Maturités liquides 1Y–60Y | Mise à jour automatique
B3: → COURBE | D3: → BOOK | G3: → PRICER | I3: → PCA RISK
B5: RISQUE PORTEFEUILLE GLOBAL
B6: DV01 TOTAL | C6: DV01 €STR | D6: DV01 EURIB6M | E6: CS01 TOTAL | G6: VAR 99% 1J | H6: CARRY 1J | I6: NB TRADES | J6: P&L JOUR
B7: =IFERROR(SUM(BOOK!Q8:Q107)+FUTURES!K81,0) -> 150310 | C7: =IFERROR(SUMIF(BOOK!F8:F107,"ESTER",BOOK!Q8:Q107),0) -> 125000 | D7: =IFERROR(SUMIF(BOOK!F8:F107,"EURIB6M",BOOK!Q8:Q107),0) -> 25000 | E7: =IFERROR(SUM(BOOK!Q8:Q107)+FUTURES!K81,0)*0.012 -> 1803.72 | G7: =IFERROR((SUM(BOOK!Q8:Q107)+FUTURES!K81)*2.33*PARAMS!C5/10000,0) -> 2101.3338 | H7: =IFERROR(SUM(BOOK!U8:U107)/365,0) -> -100342.47 | I7: =COUNTA(BOOK!B8:B107)+COUNTA(FUTURES!C31:C80) -> 6 | J7: =IFERROR(SUM(BOOK!V8:V107)+FUTURES!N81,0) -> 0
B9: DV01 PAR BUCKET DE MATURITÉ (€/pb)
B10: 1-3Y | C10: 4-5Y | D10: 6-7Y | E10: 8-10Y | G10: 11-15Y | H10: 16-20Y | I10: 21-30Y | J10: 31-50Y
B11: =IFERROR(SUMPRODUCT((BOOK!H8:H107>=1)*(BOOK!H8:H107<=3)*BOOK!Q8:Q107),0) -> 0 | C11: =IFERROR(SUMPRODUCT((BOOK!H8:H107>=4)*(BOOK!H8:H107<=5)*BOOK!Q8:Q107),0) -> 0 | D11: =IFERROR(SUMPRODUCT((BOOK!H8:H107>=6)*(BOOK!H8:H107<=7)*BOOK!Q8:Q107),0) -> 0 | E11: =IFERROR(SUMPRODUCT((BOOK!H8:H107>=8)*(BOOK!H8:H107<=10)*BOOK!Q8:Q107),0) -> 0 | G11: =IFERROR(SUMPRODUCT((BOOK!H8:H107>=11)*(BOOK!H8:H107<=15)*BOOK!Q8:Q107),0) -> 0 | H11: =IFERROR(SUMPRODUCT((BOOK!H8:H107>=16)*(BOOK!H8:H107<=20)*BOOK!Q8:Q107),0) -> 0 | I11: =IFERROR(SUMPRODUCT((BOOK!H8:H107>=21)*(BOOK!H8:H107<=30)*BOOK!Q8:Q107),0) -> 0 | J11: =IFERROR(SUMPRODUCT((BOOK!H8:H107>=31)*(BOOK!H8:H107<=60)*BOOK!Q8:Q107),0) -> 0
B13: SNAPSHOT COURBE BUMPED (€STR OIS %)
B14: 1Y | C14: 2Y | D14: 3Y | E14: 5Y | F14: 7Y | G14: 10Y | H14: 15Y | I14: 20Y | J14: 30Y | K14: 50Y
B15: =COURBE!G8 -> 0 | C15: =COURBE!G9 -> 0 | D15: =COURBE!G10 -> 0 | E15: =COURBE!G12 -> 0 | F15: =COURBE!G14 -> 0 | G15: =COURBE!G17 -> 0 | H15: =COURBE!G20 -> 0 | I15: =COURBE!G21 -> 0 | J15: =COURBE!G23 -> 0 | K15: =COURBE!G26 -> 0
B17: TOP 5 POSITIONS PAR DV01 ABSOLU
B18: Trade ID | C18: Contrepartie | D18: Type | E18: Index | F18: Mat. | G18: Notionnel (M€) | H18: DV01 (€) | I18: P&L Jour (€)
B19: =IFERROR(INDEX(BOOK!B$8:B$107,MATCH(LARGE(ABS(BOOK!$Q$8:$Q$107),1),ABS(BOOK!$Q$8:$Q$107),0)),"") | C19: =IFERROR(INDEX(BOOK!C$8:C$107,MATCH(LARGE(ABS(BOOK!$Q$8:$Q$107),1),ABS(BOOK!$Q$8:$Q$107),0)),"") | D19: =IFERROR(INDEX(BOOK!D$8:D$107,MATCH(LARGE(ABS(BOOK!$Q$8:$Q$107),1),ABS(BOOK!$Q$8:$Q$107),0)),"") | E19: =IFERROR(INDEX(BOOK!F$8:F$107,MATCH(LARGE(ABS(BOOK!$Q$8:$Q$107),1),ABS(BOOK!$Q$8:$Q$107),0)),"") | F19: =IFERROR(INDEX(BOOK!H$8:H$107,MATCH(LARGE(ABS(BOOK!$Q$8:$Q$107),1),ABS(BOOK!$Q$8:$Q$107),0)),"") | G19: =IFERROR(INDEX(BOOK!I$8:I$107,MATCH(LARGE(ABS(BOOK!$Q$8:$Q$107),1),ABS(BOOK!$Q$8:$Q$107),0)),"") | H19: =IFERROR(INDEX(BOOK!Q$8:Q$107,MATCH(LARGE(ABS(BOOK!$Q$8:$Q$107),1),ABS(BOOK!$Q$8:$Q$107),0)),"") | I19: =IFERROR(INDEX(BOOK!V$8:V$107,MATCH(LARGE(ABS(BOOK!$Q$8:$Q$107),1),ABS(BOOK!$Q$8:$Q$107),0)),"")
B20: =IFERROR(INDEX(BOOK!B$8:B$107,MATCH(LARGE(ABS(BOOK!$Q$8:$Q$107),2),ABS(BOOK!$Q$8:$Q$107),0)),"") | C20: =IFERROR(INDEX(BOOK!C$8:C$107,MATCH(LARGE(ABS(BOOK!$Q$8:$Q$107),2),ABS(BOOK!$Q$8:$Q$107),0)),"") | D20: =IFERROR(INDEX(BOOK!D$8:D$107,MATCH(LARGE(ABS(BOOK!$Q$8:$Q$107),2),ABS(BOOK!$Q$8:$Q$107),0)),"") | E20: =IFERROR(INDEX(BOOK!F$8:F$107,MATCH(LARGE(ABS(BOOK!$Q$8:$Q$107),2),ABS(BOOK!$Q$8:$Q$107),0)),"") | F20: =IFERROR(INDEX(BOOK!H$8:H$107,MATCH(LARGE(ABS(BOOK!$Q$8:$Q$107),2),ABS(BOOK!$Q$8:$Q$107),0)),"") | G20: =IFERROR(INDEX(BOOK!I$8:I$107,MATCH(LARGE(ABS(BOOK!$Q$8:$Q$107),2),ABS(BOOK!$Q$8:$Q$107),0)),"") | H20: =IFERROR(INDEX(BOOK!Q$8:Q$107,MATCH(LARGE(ABS(BOOK!$Q$8:$Q$107),2),ABS(BOOK!$Q$8:$Q$107),0)),"") | I20: =IFERROR(INDEX(BOOK!V$8:V$107,MATCH(LARGE(ABS(BOOK!$Q$8:$Q$107),2),ABS(BOOK!$Q$8:$Q$107),0)),"")
B21: =IFERROR(INDEX(BOOK!B$8:B$107,MATCH(LARGE(ABS(BOOK!$Q$8:$Q$107),3),ABS(BOOK!$Q$8:$Q$107),0)),"") | C21: =IFERROR(INDEX(BOOK!C$8:C$107,MATCH(LARGE(ABS(BOOK!$Q$8:$Q$107),3),ABS(BOOK!$Q$8:$Q$107),0)),"") | D21: =IFERROR(INDEX(BOOK!D$8:D$107,MATCH(LARGE(ABS(BOOK!$Q$8:$Q$107),3),ABS(BOOK!$Q$8:$Q$107),0)),"") | E21: =IFERROR(INDEX(BOOK!F$8:F$107,MATCH(LARGE(ABS(BOOK!$Q$8:$Q$107),3),ABS(BOOK!$Q$8:$Q$107),0)),"") | F21: =IFERROR(INDEX(BOOK!H$8:H$107,MATCH(LARGE(ABS(BOOK!$Q$8:$Q$107),3),ABS(BOOK!$Q$8:$Q$107),0)),"") | G21: =IFERROR(INDEX(BOOK!I$8:I$107,MATCH(LARGE(ABS(BOOK!$Q$8:$Q$107),3),ABS(BOOK!$Q$8:$Q$107),0)),"") | H21: =IFERROR(INDEX(BOOK!Q$8:Q$107,MATCH(LARGE(ABS(BOOK!$Q$8:$Q$107),3),ABS(BOOK!$Q$8:$Q$107),0)),"") | I21: =IFERROR(INDEX(BOOK!V$8:V$107,MATCH(LARGE(ABS(BOOK!$Q$8:$Q$107),3),ABS(BOOK!$Q$8:$Q$107),0)),"")
B22: =IFERROR(INDEX(BOOK!B$8:B$107,MATCH(LARGE(ABS(BOOK!$Q$8:$Q$107),4),ABS(BOOK!$Q$8:$Q$107),0)),"") | C22: =IFERROR(INDEX(BOOK!C$8:C$107,MATCH(LARGE(ABS(BOOK!$Q$8:$Q$107),4),ABS(BOOK!$Q$8:$Q$107),0)),"") | D22: =IFERROR(INDEX(BOOK!D$8:D$107,MATCH(LARGE(ABS(BOOK!$Q$8:$Q$107),4),ABS(BOOK!$Q$8:$Q$107),0)),"") | E22: =IFERROR(INDEX(BOOK!F$8:F$107,MATCH(LARGE(ABS(BOOK!$Q$8:$Q$107),4),ABS(BOOK!$Q$8:$Q$107),0)),"") | F22: =IFERROR(INDEX(BOOK!H$8:H$107,MATCH(LARGE(ABS(BOOK!$Q$8:$Q$107),4),ABS(BOOK!$Q$8:$Q$107),0)),"") | G22: =IFERROR(INDEX(BOOK!I$8:I$107,MATCH(LARGE(ABS(BOOK!$Q$8:$Q$107),4),ABS(BOOK!$Q$8:$Q$107),0)),"") | H22: =IFERROR(INDEX(BOOK!Q$8:Q$107,MATCH(LARGE(ABS(BOOK!$Q$8:$Q$107),4),ABS(BOOK!$Q$8:$Q$107),0)),"") | I22: =IFERROR(INDEX(BOOK!V$8:V$107,MATCH(LARGE(ABS(BOOK!$Q$8:$Q$107),4),ABS(BOOK!$Q$8:$Q$107),0)),"")
B23: =IFERROR(INDEX(BOOK!B$8:B$107,MATCH(LARGE(ABS(BOOK!$Q$8:$Q$107),5),ABS(BOOK!$Q$8:$Q$107),0)),"") | C23: =IFERROR(INDEX(BOOK!C$8:C$107,MATCH(LARGE(ABS(BOOK!$Q$8:$Q$107),5),ABS(BOOK!$Q$8:$Q$107),0)),"") | D23: =IFERROR(INDEX(BOOK!D$8:D$107,MATCH(LARGE(ABS(BOOK!$Q$8:$Q$107),5),ABS(BOOK!$Q$8:$Q$107),0)),"") | E23: =IFERROR(INDEX(BOOK!F$8:F$107,MATCH(LARGE(ABS(BOOK!$Q$8:$Q$107),5),ABS(BOOK!$Q$8:$Q$107),0)),"") | F23: =IFERROR(INDEX(BOOK!H$8:H$107,MATCH(LARGE(ABS(BOOK!$Q$8:$Q$107),5),ABS(BOOK!$Q$8:$Q$107),0)),"") | G23: =IFERROR(INDEX(BOOK!I$8:I$107,MATCH(LARGE(ABS(BOOK!$Q$8:$Q$107),5),ABS(BOOK!$Q$8:$Q$107),0)),"") | H23: =IFERROR(INDEX(BOOK!Q$8:Q$107,MATCH(LARGE(ABS(BOOK!$Q$8:$Q$107),5),ABS(BOOK!$Q$8:$Q$107),0)),"") | I23: =IFERROR(INDEX(BOOK!V$8:V$107,MATCH(LARGE(ABS(BOOK!$Q$8:$Q$107),5),ABS(BOOK!$Q$8:$Q$107),0)),"")
B25: ALERTES RISQUE
B26: DV01 Total > Limite | E26: VAR > Limite | H26: Nb Trades max
B27: =IF(ABS(B7)>PARAMS!C6,"⚠ DÉPASSEMENT LIMITE","✓ OK") -> ✓ OK | E27: =IF(ABS(H7)>PARAMS!C7,"⚠ DÉPASSEMENT VAR","✓ OK") -> ✓ OK | H27: =IF(I7>PARAMS!C8,"⚠ MAX ATTEINT","✓ OK") -> ✓ OK

Sheet COURBE
A1: COURBE DE TAUX IRS EURO · €STR OIS & EURIBOR 6M · BUMPS INTERACTIFS
A2: Bleu = saisie | Noir = formule | Vert = lien inter-onglet | F9 = recalcul
A4: BUMPS → | C4: Parallèle (pb) | D4: 0 | E4: Tilt (pb/an) | F4: 0 | G4: Twist (pb) | H4: 0 | I4: Fly Wing (pb) | J4: 0 | K4: Basis +/- (pb) | L4: 0
A6: # | B6: Mat. | C6: €STR Base | D6: E6M Base | E6: Δ Para. | F6: Δ Tilt | G6: Δ Twist | H6: €STR Bumped | I6: E6M Bumped | J6: Fwd €STR | K6: Fwd E6M | L6: DF €STR | M6: DF E6M | N6: Basis (pb)
A8: 1 | B8: 1Y | C8: 0.0355 | D8: 0.0365 | E8: =$D$4 -> 0 | F8: =$F$4*1 -> 0 | G8: =$H$4*1 -> 0 | H8: =C8+(E8+F8+G8)/10000 -> 0.0355 | I8: =D8+(E8+F8+G8+$L$4)/10000 -> 0.0365 | J8: =H8 -> 0.0355 | K8: =I8 -> 0.0365 | L8: =(1+H8)^(-1) -> 0.96571704 | M8: =(1+I8)^(-1) -> 0.96478534 | N8: =(I8-H8)*10000 -> 10
A9: 2 | B9: 2Y | C9: 0.032 | D9: 0.033 | E9: =$D$4 -> 0 | F9: =$F$4*2 -> 0 | G9: =$H$4*1 -> 0 | H9: =C9+(E9+F9+G9)/10000 -> 0.032 | I9: =D9+(E9+F9+G9+$L$4)/10000 -> 0.033 | J9: =IFERROR((L8/L9)^(1/1)-1,H9) -> 0.02851183 | K9: =IFERROR((M8/M9)^(1/1)-1,I9) -> 0.029511819 | L9: =(1+H9)^(-2) -> 0.93894598 | M9: =(1+I9)^(-2) -> 0.93712896 | N9: =(I9-H9)*10000 -> 10
A10: 3 | B10: 3Y | C10: 0.0295 | D10: 0.0305 | E10: =$D$4 -> 0 | F10: =$F$4*3 -> 0 | G10: =$H$4*1 -> 0 | H10: =C10+(E10+F10+G10)/10000 -> 0.0295 | I10: =D10+(E10+F10+G10+$L$4)/10000 -> 0.0305 | J10: =IFERROR((L9/L10)^(1/1)-1,H10) -> 0.024518154 | K10: =IFERROR((M9/M10)^(1/1)-1,I10) -> 0.025518136 | L10: =(1+H10)^(-3) -> 0.91647568 | M10: =(1+I10)^(-3) -> 0.91381022 | N10: =(I10-H10)*10000 -> 10
A11: 4 | B11: 4Y | C11: 0.0278 | D11: 0.0288 | E11: =$D$4 -> 0 | F11: =$F$4*4 -> 0 | G11: =$H$4*1 -> 0 | H11: =C11+(E11+F11+G11)/10000 -> 0.0278 | I11: =D11+(E11+F11+G11+$L$4)/10000 -> 0.0288 | J11: =IFERROR((L10/L11)^(1/1)-1,H11) -> 0.022716825 | K11: =IFERROR((M10/M11)^(1/1)-1,I11) -> 0.023716808 | L11: =(1+H11)^(-4) -> 0.89611871 | M11: =(1+I11)^(-4) -> 0.89263966 | N11: =(I11-H11)*10000 -> 10
A12: 5 | B12: 5Y | C12: 0.0268 | D12: 0.0278 | E12: =$D$4 -> 0 | F12: =$F$4*5 -> 0 | G12: =$H$4*1 -> 0 | H12: =C12+(E12+F12+G12)/10000 -> 0.0268 | I12: =D12+(E12+F12+G12+$L$4)/10000 -> 0.0278 | J12: =IFERROR((L11/L12)^(1/1)-1,H12) -> 0.02280972 | K12: =IFERROR((M11/M12)^(1/1)-1,I12) -> 0.023809711 | L12: =(1+H12)^(-5) -> 0.87613433 | M12: =(1+I12)^(-5) -> 0.87188044 | N12: =(I12-H12)*10000 -> 10
A13: 6 | B13: 6Y | C13: 0.0261 | D13: 0.0271 | E13: =$D$4 -> 0 | F13: =$F$4*6 -> 0 | G13: =$H$4*-1 -> 0 | H13: =C13+(E13+F13+G13)/10000 -> 0.0261 | I13: =D13+(E13+F13+G13+$L$4)/10000 -> 0.0271 | J13: =IFERROR((L12/L13)^(1/1)-1,H13) -> 0.022607152 | K13: =IFERROR((M12/M13)^(1/1)-1,I13) -> 0.023607145 | L13: =(1+H13)^(-6) -> 0.85676531 | M13: =(1+I13)^(-6) -> 0.85177252 | N13: =(I13-H13)*10000 -> 10
A14: 7 | B14: 7Y | C14: 0.0257 | D14: 0.0267 | E14: =$D$4 -> 0 | F14: =$F$4*7 -> 0 | G14: =$H$4*-1 -> 0 | H14: =C14+(E14+F14+G14)/10000 -> 0.0257 | I14: =D14+(E14+F14+G14+$L$4)/10000 -> 0.0267 | J14: =IFERROR((L13/L14)^(1/1)-1,H14) -> 0.023303272 | K14: =IFERROR((M13/M14)^(1/1)-1,I14) -> 0.024303269 | L14: =(1+H14)^(-7) -> 0.83725454 | M14: =(1+I14)^(-7) -> 0.83156282 | N14: =(I14-H14)*10000 -> 10
A15: 8 | B15: 8Y | C15: 0.0254 | D15: 0.0264 | E15: =$D$4 -> 0 | F15: =$F$4*8 -> 0 | G15: =$H$4*-1 -> 0 | H15: =C15+(E15+F15+G15)/10000 -> 0.0254 | I15: =D15+(E15+F15+G15+$L$4)/10000 -> 0.0264 | J15: =IFERROR((L14/L15)^(1/1)-1,H15) -> 0.023302455 | K15: =IFERROR((M14/M15)^(1/1)-1,I15) -> 0.024302453 | L15: =(1+H15)^(-8) -> 0.81818873 | M15: =(1+I15)^(-8) -> 0.81183328 | N15: =(I15-H15)*10000 -> 10
A16: 9 | B16: 9Y | C16: 0.0253 | D16: 0.0263 | E16: =$D$4 -> 0 | F16: =$F$4*9 -> 0 | G16: =$H$4*-1 -> 0 | H16: =C16+(E16+F16+G16)/10000 -> 0.0253 | I16: =D16+(E16+F16+G16+$L$4)/10000 -> 0.0263 | J16: =IFERROR((L15/L16)^(1/1)-1,H16) -> 0.024500351 | K16: =IFERROR((M15/M16)^(1/1)-1,I16) -> 0.025500351 | L16: =(1+H16)^(-9) -> 0.79862221 | M16: =(1+I16)^(-9) -> 0.79164603 | N16: =(I16-H16)*10000 -> 10
A17: 10 | B17: 10Y | C17: 0.0252 | D17: 0.0262 | E17: =$D$4 -> 0 | F17: =$F$4*10 -> 0 | G17: =$H$4*-1 -> 0 | H17: =C17+(E17+F17+G17)/10000 -> 0.0252 | I17: =D17+(E17+F17+G17+$L$4)/10000 -> 0.0262 | J17: =IFERROR((L16/L17)^(1/1)-1,H17) -> 0.024300439 | K17: =IFERROR((M16/M17)^(1/1)-1,I17) -> 0.025300438 | L17: =(1+H17)^(-10) -> 0.77967575 | M17: =(1+I17)^(-10) -> 0.77211128 | N17: =(I17-H17)*10000 -> 10
A18: 11 | B18: 11Y | C18: 0.0252 | D18: 0.0262 | E18: =$D$4 -> 0 | F18: =$F$4*11 -> 0 | G18: =$H$4*-1 -> 0 | H18: =C18+(E18+F18+G18)/10000 -> 0.0252 | I18: =D18+(E18+F18+G18+$L$4)/10000 -> 0.0262 | J18: =IFERROR((L17/L18)^(1/1)-1,H18) -> 0.0252 | K18: =IFERROR((M17/M18)^(1/1)-1,I18) -> 0.0262 | L18: =(1+H18)^(-11) -> 0.76051087 | M18: =(1+I18)^(-11) -> 0.75239844 | N18: =(I18-H18)*10000 -> 10
A19: 12 | B19: 12Y | C19: 0.0253 | D19: 0.0263 | E19: =$D$4 -> 0 | F19: =$F$4*12 -> 0 | G19: =$H$4*-1 -> 0 | H19: =C19+(E19+F19+G19)/10000 -> 0.0253 | I19: =D19+(E19+F19+G19+$L$4)/10000 -> 0.0263 | J19: =IFERROR((L18/L19)^(1/1)-1,H19) -> 0.026400644 | K19: =IFERROR((M18/M19)^(1/1)-1,I19) -> 0.027400643 | L19: =(1+H19)^(-12) -> 0.74094933 | M19: =(1+I19)^(-12) -> 0.73233207 | N19: =(I19-H19)*10000 -> 10
A20: 13 | B20: 15Y | C20: 0.0256 | D20: 0.0266 | E20: =$D$4 -> 0 | F20: =$F$4*15 -> 0 | G20: =$H$4*-1 -> 0 | H20: =C20+(E20+F20+G20)/10000 -> 0.0256 | I20: =D20+(E20+F20+G20+$L$4)/10000 -> 0.0266 | J20: =IFERROR((L19/L20)^(1/3)-1,H20) -> 0.026800878 | K20: =IFERROR((M19/M20)^(1/3)-1,I20) -> 0.027800877 | L20: =(1+H20)^(-15) -> 0.68443123 | M20: =(1+I20)^(-15) -> 0.67449868 | N20: =(I20-H20)*10000 -> 10
A21: 14 | B21: 20Y | C21: 0.0255 | D21: 0.0265 | E21: =$D$4 -> 0 | F21: =$F$4*20 -> 0 | G21: =$H$4*1 -> 0 | H21: =C21+(E21+F21+G21)/10000 -> 0.0255 | I21: =D21+(E21+F21+G21+$L$4)/10000 -> 0.0265 | J21: =IFERROR((L20/L21)^(1/5)-1,H21) -> 0.025200058 | K21: =IFERROR((M20/M21)^(1/5)-1,I21) -> 0.026200058 | L21: =(1+H21)^(-20) -> 0.60434747 | M21: =(1+I21)^(-20) -> 0.59268089 | N21: =(I21-H21)*10000 -> 10
A22: 15 | B22: 25Y | C22: 0.025 | D22: 0.026 | E22: =$D$4 -> 0 | F22: =$F$4*25 -> 0 | G22: =$H$4*1 -> 0 | H22: =C22+(E22+F22+G22)/10000 -> 0.025 | I22: =D22+(E22+F22+G22+$L$4)/10000 -> 0.026 | J22: =IFERROR((L21/L22)^(1/5)-1,H22) -> 0.023002437 | K22: =IFERROR((M21/M22)^(1/5)-1,I22) -> 0.024002434 | L22: =(1+H22)^(-25) -> 0.53939059 | M22: =(1+I22)^(-25) -> 0.52640012 | N22: =(I22-H22)*10000 -> 10
A23: 16 | B23: 30Y | C23: 0.0245 | D23: 0.0255 | E23: =$D$4 -> 0 | F23: =$F$4*30 -> 0 | G23: =$H$4*1 -> 0 | H23: =C23+(E23+F23+G23)/10000 -> 0.0245 | I23: =D23+(E23+F23+G23+$L$4)/10000 -> 0.0255 | J23: =IFERROR((L22/L23)^(1/5)-1,H23) -> 0.022003656 | K23: =IFERROR((M22/M23)^(1/5)-1,I23) -> 0.023003653 | L23: =(1+H23)^(-30) -> 0.48377243 | M23: =(1+I23)^(-30) -> 0.46981844 | N23: =(I23-H23)*10000 -> 10
A24: 17 | B24: 35Y | C24: 0.024 | D24: 0.025 | E24: =$D$4 -> 0 | F24: =$F$4*35 -> 0 | G24: =$H$4*1 -> 0 | H24: =C24+(E24+F24+G24)/10000 -> 0.024 | I24: =D24+(E24+F24+G24+$L$4)/10000 -> 0.025 | J24: =IFERROR((L23/L24)^(1/5)-1,H24) -> 0.02100512 | K24: =IFERROR((M23/M24)^(1/5)-1,I24) -> 0.022005115 | L24: =(1+H24)^(-35) -> 0.43601509 | M24: =(1+I24)^(-35) -> 0.42137107 | N24: =(I24-H24)*10000 -> 10
A25: 18 | B25: 40Y | C25: 0.0237 | D25: 0.0247 | E25: =$D$4 -> 0 | F25: =$F$4*40 -> 0 | G25: =$H$4*1 -> 0 | H25: =C25+(E25+F25+G25)/10000 -> 0.0237 | I25: =D25+(E25+F25+G25+$L$4)/10000 -> 0.0247 | J25: =IFERROR((L24/L25)^(1/5)-1,H25) -> 0.021602459 | K25: =IFERROR((M24/M25)^(1/5)-1,I25) -> 0.022602457 | L25: =(1+H25)^(-40) -> 0.39182475 | M25: =(1+I25)^(-40) -> 0.37681706 | N25: =(I25-H25)*10000 -> 10
A26: 19 | B26: 50Y | C26: 0.023 | D26: 0.024 | E26: =$D$4 -> 0 | F26: =$F$4*50 -> 0 | G26: =$H$4*1 -> 0 | H26: =C26+(E26+F26+G26)/10000 -> 0.023 | I26: =D26+(E26+F26+G26+$L$4)/10000 -> 0.024 | J26: =IFERROR((L25/L26)^(1/10)-1,H26) -> 0.020204783 | K26: =IFERROR((M25/M26)^(1/10)-1,I26) -> 0.021204779 | L26: =(1+H26)^(-50) -> 0.32078815 | M26: =(1+I26)^(-50) -> 0.30549364 | N26: =(I26-H26)*10000 -> 10
A27: 20 | B27: 60Y | C27: 0.0222 | D27: 0.0232 | E27: =$D$4 -> 0 | F27: =$F$4*60 -> 0 | G27: =$H$4*1 -> 0 | H27: =C27+(E27+F27+G27)/10000 -> 0.0222 | I27: =D27+(E27+F27+G27+$L$4)/10000 -> 0.0232 | J27: =IFERROR((L26/L27)^(1/10)-1,H27) -> 0.018209374 | K27: =IFERROR((M26/M27)^(1/10)-1,I27) -> 0.019209365 | L27: =(1+H27)^(-60) -> 0.26782271 | M27: =(1+I27)^(-60) -> 0.25256206 | N27: =(I27-H27)*10000 -> 10
A29: STATISTIQUES COURBE BUMPED
C30: Min €STR | D30: Max €STR | E30: 2-10 spread | F30: 10-30 spread | H30: Min E6M | I30: Max E6M | J30: Basis moy | K30: Twist val
C31: =MIN(H8:H27) -> 0.0222 | D31: =MAX(H8:H27) -> 0.0355 | E31: =(H17-H9)*10000 -> -68 | F31: =(H23-H17)*10000 -> -7 | H31: =MIN(I8:I27) -> 0.0232 | I31: =MAX(I8:I27) -> 0.0365 | J31: =AVERAGE(N8:N27) -> 10 | K31: =(2*H17-H9-H23)*10000 -> -61

Sheet BOOK
A1: BOOK DE POSITIONS IRS EURO · GESTION DES TRADES
A2: Saisie directe dans les colonnes bleues | Calculs automatiques | Jusqu'à 100 trades
A4: SAISIE: Remplir les colonnes bleues (B à K). Les colonnes grises sont calculées automatiquement.
A6: # | B6: IDENTIFICATION | E6: STRUCTURE | I6: TAUX (%) | L6: RISQUE (€) | O6: DV01 & BPV | R6: CARRY / ROLL | U6: P&L
A7: # | B7: Trade ID | C7: Contrepartie | D7: Date Trade | E7: Échéance | F7: Index | G7: Direction | H7: Mat(Y) | I7: Notionnel(M€) | J7: Taux Fixe% | K7: Spread Flot(pb) | L7: Taux Fixe | M7: Taux Flot | N7: Spread | O7: DV01(€/pb) | P7: BPV(€) | Q7: DV01 Net | R7: Carry 1J(€) | S7: Roll 3M(pb) | T7: Total R+C | U7: NPV(€) | V7: P&L Jour(€) | W7: Commentaire
A8: 1 | B8: TR-001 | C8: BNP Paribas | D8: 15/01/2025 | E8: 15/01/2035 | F8: ESTER | G8: PAY | H8: 10 | I8: 100 | J8: 2.52 | K8: 0 | L8: =IF(J8="","",J8/100) -> 0.0252 | M8: =IF(H8="","",IFERROR(VLOOKUP(H8*1,COURBE!$B$8:$N$27,IF(F8="ESTER",7,8),0),0)) -> 0 | N8: =IF(L8="","",IF(G8="PAY",M8-L8,L8-M8)) -> -0.0252 | O8: =IF(H8="","",IF(G8="PAY",-1,1)*I8*1000000*H8/10000) -> -100000 | P8: =IF(H8="","",I8*1000000*L8*H8/10000) -> 2520 | Q8: =IF(O8="","",O8) -> -100000 | R8: =IF(L8="","",IF(G8="PAY",(M8-L8),-( M8-L8))*I8*1000000/365) -> -6904.1096 | S8: =IF(H8="","",IFERROR((VLOOKUP(H8*1,COURBE!$B$8:$N$27,IF(F8="ESTER",7,8),0)-VLOOKUP(MAX(H8-1,1),COURBE!$B$8:$N$27,IF(F8="ESTER",7,8),0))*10000,0)) -> 0 | T8: =IF(R8="","",R8*90+IF(S8="",0,S8)*I8*1000000/10000*H8/365) -> -621369.86 | U8: =IF(L8="","",O8*(M8-L8)*10000) -> 25200000 | V8: =IF(O8="","",0) -> 0
A9: 2 | B9: TR-002 | C9: SG CIB | D9: 01/03/2025 | E9: 01/03/2030 | F9: EURIB6M | G9: RECEIVE | H9: 5 | I9: 50 | J9: 2.68 | K9: 0 | L9: =IF(J9="","",J9/100) -> 0.0268 | M9: =IF(H9="","",IFERROR(VLOOKUP(H9*1,COURBE!$B$8:$N$27,IF(F9="ESTER",7,8),0),0)) -> 0 | N9: =IF(L9="","",IF(G9="PAY",M9-L9,L9-M9)) -> 0.0268 | O9: =IF(H9="","",IF(G9="PAY",-1,1)*I9*1000000*H9/10000) -> 25000 | P9: =IF(H9="","",I9*1000000*L9*H9/10000) -> 670 | Q9: =IF(O9="","",O9) -> 25000 | R9: =IF(L9="","",IF(G9="PAY",(M9-L9),-( M9-L9))*I9*1000000/365) -> 3671.2329 | S9: =IF(H9="","",IFERROR((VLOOKUP(H9*1,COURBE!$B$8:$N$27,IF(F9="ESTER",7,8),0)-VLOOKUP(MAX(H9-1,1),COURBE!$B$8:$N$27,IF(F9="ESTER",7,8),0))*10000,0)) -> 0 | T9: =IF(R9="","",R9*90+IF(S9="",0,S9)*I9*1000000/10000*H9/365) -> 330410.96 | U9: =IF(L9="","",O9*(M9-L9)*10000) -> -6700000 | V9: =IF(O9="","",0) -> 0
A10: 3 | B10: TR-003 | C10: Deutsche Bank | D10: 10/02/2025 | E10: 10/02/2055 | F10: ESTER | G10: RECEIVE | H10: 30 | I10: 75 | J10: 2.45 | K10: 0 | L10: =IF(J10="","",J10/100) -> 0.0245 | M10: =IF(H10="","",IFERROR(VLOOKUP(H10*1,COURBE!$B$8:$N$27,IF(F10="ESTER",7,8),0),0)) -> 0 | N10: =IF(L10="","",IF(G10="PAY",M10-L10,L10-M10)) -> 0.0245 | O10: =IF(H10="","",IF(G10="PAY",-1,1)*I10*1000000*H10/10000) -> 225000 | P10: =IF(H10="","",I10*1000000*L10*H10/10000) -> 5512.5 | Q10: =IF(O10="","",O10) -> 225000 | R10: =IF(L10="","",IF(G10="PAY",(M10-L10),-( M10-L10))*I10*1000000/365) -> 5034.2466 | S10: =IF(H10="","",IFERROR((VLOOKUP(H10*1,COURBE!$B$8:$N$27,IF(F10="ESTER",7,8),0)-VLOOKUP(MAX(H10-1,1),COURBE!$B$8:$N$27,IF(F10="ESTER",7,8),0))*10000,0)) -> 0 | T10: =IF(R10="","",R10*90+IF(S10="",0,S10)*I10*1000000/10000*H10/365) -> 453082.19 | U10: =IF(L10="","",O10*(M10-L10)*10000) -> -55125000 | V10: =IF(O10="","",0) -> 0
A11: 4 | L11: =IF(J11="","",J11/100) | M11: =IF(H11="","",IFERROR(VLOOKUP(H11*1,COURBE!$B$8:$N$27,IF(F11="ESTER",7,8),0),0)) | N11: =IF(L11="","",IF(G11="PAY",M11-L11,L11-M11)) | O11: =IF(H11="","",IF(G11="PAY",-1,1)*I11*1000000*H11/10000) | P11: =IF(H11="","",I11*1000000*L11*H11/10000) | Q11: =IF(O11="","",O11) | R11: =IF(L11="","",IF(G11="PAY",(M11-L11),-( M11-L11))*I11*1000000/365) | S11: =IF(H11="","",IFERROR((VLOOKUP(H11*1,COURBE!$B$8:$N$27,IF(F11="ESTER",7,8),0)-VLOOKUP(MAX(H11-1,1),COURBE!$B$8:$N$27,IF(F11="ESTER",7,8),0))*10000,0)) | T11: =IF(R11="","",R11*90+IF(S11="",0,S11)*I11*1000000/10000*H11/365) | U11: =IF(L11="","",O11*(M11-L11)*10000) | V11: =IF(O11="","",0)
A12: 5 | L12: =IF(J12="","",J12/100) | M12: =IF(H12="","",IFERROR(VLOOKUP(H12*1,COURBE!$B$8:$N$27,IF(F12="ESTER",7,8),0),0)) | N12: =IF(L12="","",IF(G12="PAY",M12-L12,L12-M12)) | O12: =IF(H12="","",IF(G12="PAY",-1,1)*I12*1000000*H12/10000) | P12: =IF(H12="","",I12*1000000*L12*H12/10000) | Q12: =IF(O12="","",O12) | R12: =IF(L12="","",IF(G12="PAY",(M12-L12),-( M12-L12))*I12*1000000/365) | S12: =IF(H12="","",IFERROR((VLOOKUP(H12*1,COURBE!$B$8:$N$27,IF(F12="ESTER",7,8),0)-VLOOKUP(MAX(H12-1,1),COURBE!$B$8:$N$27,IF(F12="ESTER",7,8),0))*10000,0)) | T12: =IF(R12="","",R12*90+IF(S12="",0,S12)*I12*1000000/10000*H12/365) | U12: =IF(L12="","",O12*(M12-L12)*10000) | V12: =IF(O12="","",0)
A13: 6 | L13: =IF(J13="","",J13/100) | M13: =IF(H13="","",IFERROR(VLOOKUP(H13*1,COURBE!$B$8:$N$27,IF(F13="ESTER",7,8),0),0)) | N13: =IF(L13="","",IF(G13="PAY",M13-L13,L13-M13)) | O13: =IF(H13="","",IF(G13="PAY",-1,1)*I13*1000000*H13/10000) | P13: =IF(H13="","",I13*1000000*L13*H13/10000) | Q13: =IF(O13="","",O13) | R13: =IF(L13="","",IF(G13="PAY",(M13-L13),-( M13-L13))*I13*1000000/365) | S13: =IF(H13="","",IFERROR((VLOOKUP(H13*1,COURBE!$B$8:$N$27,IF(F13="ESTER",7,8),0)-VLOOKUP(MAX(H13-1,1),COURBE!$B$8:$N$27,IF(F13="ESTER",7,8),0))*10000,0)) | T13: =IF(R13="","",R13*90+IF(S13="",0,S13)*I13*1000000/10000*H13/365) | U13: =IF(L13="","",O13*(M13-L13)*10000) | V13: =IF(O13="","",0)
A14: 7 | L14: =IF(J14="","",J14/100) | M14: =IF(H14="","",IFERROR(VLOOKUP(H14*1,COURBE!$B$8:$N$27,IF(F14="ESTER",7,8),0),0)) | N14: =IF(L14="","",IF(G14="PAY",M14-L14,L14-M14)) | O14: =IF(H14="","",IF(G14="PAY",-1,1)*I14*1000000*H14/10000) | P14: =IF(H14="","",I14*1000000*L14*H14/10000) | Q14: =IF(O14="","",O14) | R14: =IF(L14="","",IF(G14="PAY",(M14-L14),-( M14-L14))*I14*1000000/365) | S14: =IF(H14="","",IFERROR((VLOOKUP(H14*1,COURBE!$B$8:$N$27,IF(F14="ESTER",7,8),0)-VLOOKUP(MAX(H14-1,1),COURBE!$B$8:$N$27,IF(F14="ESTER",7,8),0))*10000,0)) | T14: =IF(R14="","",R14*90+IF(S14="",0,S14)*I14*1000000/10000*H14/365) | U14: =IF(L14="","",O14*(M14-L14)*10000) | V14: =IF(O14="","",0)
A15: 8 | L15: =IF(J15="","",J15/100) | M15: =IF(H15="","",IFERROR(VLOOKUP(H15*1,COURBE!$B$8:$N$27,IF(F15="ESTER",7,8),0),0)) | N15: =IF(L15="","",IF(G15="PAY",M15-L15,L15-M15)) | O15: =IF(H15="","",IF(G15="PAY",-1,1)*I15*1000000*H15/10000) | P15: =IF(H15="","",I15*1000000*L15*H15/10000) | Q15: =IF(O15="","",O15) | R15: =IF(L15="","",IF(G15="PAY",(M15-L15),-( M15-L15))*I15*1000000/365) | S15: =IF(H15="","",IFERROR((VLOOKUP(H15*1,COURBE!$B$8:$N$27,IF(F15="ESTER",7,8),0)-VLOOKUP(MAX(H15-1,1),COURBE!$B$8:$N$27,IF(F15="ESTER",7,8),0))*10000,0)) | T15: =IF(R15="","",R15*90+IF(S15="",0,S15)*I15*1000000/10000*H15/365) | U15: =IF(L15="","",O15*(M15-L15)*10000) | V15: =IF(O15="","",0)
A16: 9 | L16: =IF(J16="","",J16/100) | M16: =IF(H16="","",IFERROR(VLOOKUP(H16*1,COURBE!$B$8:$N$27,IF(F16="ESTER",7,8),0),0)) | N16: =IF(L16="","",IF(G16="PAY",M16-L16,L16-M16)) | O16: =IF(H16="","",IF(G16="PAY",-1,1)*I16*1000000*H16/10000) | P16: =IF(H16="","",I16*1000000*L16*H16/10000) | Q16: =IF(O16="","",O16) | R16: =IF(L16="","",IF(G16="PAY",(M16-L16),-( M16-L16))*I16*1000000/365) | S16: =IF(H16="","",IFERROR((VLOOKUP(H16*1,COURBE!$B$8:$N$27,IF(F16="ESTER",7,8),0)-VLOOKUP(MAX(H16-1,1),COURBE!$B$8:$N$27,IF(F16="ESTER",7,8),0))*10000,0)) | T16: =IF(R16="","",R16*90+IF(S16="",0,S16)*I16*1000000/10000*H16/365) | U16: =IF(L16="","",O16*(M16-L16)*10000) | V16: =IF(O16="","",0)
A17: 10 | L17: =IF(J17="","",J17/100) | M17: =IF(H17="","",IFERROR(VLOOKUP(H17*1,COURBE!$B$8:$N$27,IF(F17="ESTER",7,8),0),0)) | N17: =IF(L17="","",IF(G17="PAY",M17-L17,L17-M17)) | O17: =IF(H17="","",IF(G17="PAY",-1,1)*I17*1000000*H17/10000) | P17: =IF(H17="","",I17*1000000*L17*H17/10000) | Q17: =IF(O17="","",O17) | R17: =IF(L17="","",IF(G17="PAY",(M17-L17),-( M17-L17))*I17*1000000/365) | S17: =IF(H17="","",IFERROR((VLOOKUP(H17*1,COURBE!$B$8:$N$27,IF(F17="ESTER",7,8),0)-VLOOKUP(MAX(H17-1,1),COURBE!$B$8:$N$27,IF(F17="ESTER",7,8),0))*10000,0)) | T17: =IF(R17="","",R17*90+IF(S17="",0,S17)*I17*1000000/10000*H17/365) | U17: =IF(L17="","",O17*(M17-L17)*10000) | V17: =IF(O17="","",0)
A18: 11 | L18: =IF(J18="","",J18/100) | M18: =IF(H18="","",IFERROR(VLOOKUP(H18*1,COURBE!$B$8:$N$27,IF(F18="ESTER",7,8),0),0)) | N18: =IF(L18="","",IF(G18="PAY",M18-L18,L18-M18)) | O18: =IF(H18="","",IF(G18="PAY",-1,1)*I18*1000000*H18/10000) | P18: =IF(H18="","",I18*1000000*L18*H18/10000) | Q18: =IF(O18="","",O18) | R18: =IF(L18="","",IF(G18="PAY",(M18-L18),-( M18-L18))*I18*1000000/365) | S18: =IF(H18="","",IFERROR((VLOOKUP(H18*1,COURBE!$B$8:$N$27,IF(F18="ESTER",7,8),0)-VLOOKUP(MAX(H18-1,1),COURBE!$B$8:$N$27,IF(F18="ESTER",7,8),0))*10000,0)) | T18: =IF(R18="","",R18*90+IF(S18="",0,S18)*I18*1000000/10000*H18/365) | U18: =IF(L18="","",O18*(M18-L18)*10000) | V18: =IF(O18="","",0)
A19: 12 | L19: =IF(J19="","",J19/100) | M19: =IF(H19="","",IFERROR(VLOOKUP(H19*1,COURBE!$B$8:$N$27,IF(F19="ESTER",7,8),0),0)) | N19: =IF(L19="","",IF(G19="PAY",M19-L19,L19-M19)) | O19: =IF(H19="","",IF(G19="PAY",-1,1)*I19*1000000*H19/10000) | P19: =IF(H19="","",I19*1000000*L19*H19/10000) | Q19: =IF(O19="","",O19) | R19: =IF(L19="","",IF(G19="PAY",(M19-L19),-( M19-L19))*I19*1000000/365) | S19: =IF(H19="","",IFERROR((VLOOKUP(H19*1,COURBE!$B$8:$N$27,IF(F19="ESTER",7,8),0)-VLOOKUP(MAX(H19-1,1),COURBE!$B$8:$N$27,IF(F19="ESTER",7,8),0))*10000,0)) | T19: =IF(R19="","",R19*90+IF(S19="",0,S19)*I19*1000000/10000*H19/365) | U19: =IF(L19="","",O19*(M19-L19)*10000) | V19: =IF(O19="","",0)
A20: 13 | L20: =IF(J20="","",J20/100) | M20: =IF(H20="","",IFERROR(VLOOKUP(H20*1,COURBE!$B$8:$N$27,IF(F20="ESTER",7,8),0),0)) | N20: =IF(L20="","",IF(G20="PAY",M20-L20,L20-M20)) | O20: =IF(H20="","",IF(G20="PAY",-1,1)*I20*1000000*H20/10000) | P20: =IF(H20="","",I20*1000000*L20*H20/10000) | Q20: =IF(O20="","",O20) | R20: =IF(L20="","",IF(G20="PAY",(M20-L20),-( M20-L20))*I20*1000000/365) | S20: =IF(H20="","",IFERROR((VLOOKUP(H20*1,COURBE!$B$8:$N$27,IF(F20="ESTER",7,8),0)-VLOOKUP(MAX(H20-1,1),COURBE!$B$8:$N$27,IF(F20="ESTER",7,8),0))*10000,0)) | T20: =IF(R20="","",R20*90+IF(S20="",0,S20)*I20*1000000/10000*H20/365) | U20: =IF(L20="","",O20*(M20-L20)*10000) | V20: =IF(O20="","",0)
A21: 14 | L21: =IF(J21="","",J21/100) | M21: =IF(H21="","",IFERROR(VLOOKUP(H21*1,COURBE!$B$8:$N$27,IF(F21="ESTER",7,8),0),0)) | N21: =IF(L21="","",IF(G21="PAY",M21-L21,L21-M21)) | O21: =IF(H21="","",IF(G21="PAY",-1,1)*I21*1000000*H21/10000) | P21: =IF(H21="","",I21*1000000*L21*H21/10000) | Q21: =IF(O21="","",O21) | R21: =IF(L21="","",IF(G21="PAY",(M21-L21),-( M21-L21))*I21*1000000/365) | S21: =IF(H21="","",IFERROR((VLOOKUP(H21*1,COURBE!$B$8:$N$27,IF(F21="ESTER",7,8),0)-VLOOKUP(MAX(H21-1,1),COURBE!$B$8:$N$27,IF(F21="ESTER",7,8),0))*10000,0)) | T21: =IF(R21="","",R21*90+IF(S21="",0,S21)*I21*1000000/10000*H21/365) | U21: =IF(L21="","",O21*(M21-L21)*10000) | V21: =IF(O21="","",0)
A22: 15 | L22: =IF(J22="","",J22/100) | M22: =IF(H22="","",IFERROR(VLOOKUP(H22*1,COURBE!$B$8:$N$27,IF(F22="ESTER",7,8),0),0)) | N22: =IF(L22="","",IF(G22="PAY",M22-L22,L22-M22)) | O22: =IF(H22="","",IF(G22="PAY",-1,1)*I22*1000000*H22/10000) | P22: =IF(H22="","",I22*1000000*L22*H22/10000) | Q22: =IF(O22="","",O22) | R22: =IF(L22="","",IF(G22="PAY",(M22-L22),-( M22-L22))*I22*1000000/365) | S22: =IF(H22="","",IFERROR((VLOOKUP(H22*1,COURBE!$B$8:$N$27,IF(F22="ESTER",7,8),0)-VLOOKUP(MAX(H22-1,1),COURBE!$B$8:$N$27,IF(F22="ESTER",7,8),0))*10000,0)) | T22: =IF(R22="","",R22*90+IF(S22="",0,S22)*I22*1000000/10000*H22/365) | U22: =IF(L22="","",O22*(M22-L22)*10000) | V22: =IF(O22="","",0)
... A107: 100 | L107: =IF(J107="","",J107/100) | M107: =IF(H107="","",IFERROR(VLOOKUP(H107*1,COURBE!$B$8:$N$27,IF(F107="ESTER",7,8),0),0)) | N107: =IF(L107="","",IF(G107="PAY",M107-L107,L107-M107)) | O107: =IF(H107="","",IF(G107="PAY",-1,1)*I107*1000000*H107/10000) | P107: =IF(H107="","",I107*1000000*L107*H107/10000) | Q107: =IF(O107="","",O107) | R107: =IF(L107="","",IF(G107="PAY",(M107-L107),-( M107-L107))*I107*1000000/365) | S107: =IF(H107="","",IFERROR((VLOOKUP(H107*1,COURBE!$B$8:$N$27,IF(F107="ESTER",7,8),0)-VLOOKUP(MAX(H107-1,1),COURBE!$B$8:$N$27,IF(F107="ESTER",7,8),0))*10000,0)) | T107: =IF(R107="","",R107*90+IF(S107="",0,S107)*I107*1000000/10000*H107/365) | U107: =IF(L107="","",O107*(M107-L107)*10000) | V107: =IF(O107="","",0)
A109: TOTAUX PORTEFEUILLE | O109: =SUM(O8:O107) -> 150000 | P109: =SUM(P8:P107) -> 8702.5 | Q109: =SUM(Q8:Q107) -> 150000 | R109: =SUM(R8:R107) -> 1801.3699 | T109: =SUM(T8:T107) -> 162123.29 | U109: =SUM(U8:U107) -> -36625000 | V109: =SUM(V8:V107) -> 0

Sheet PRICER
B1: PRICER IRS EURO UNIQUE · €STR OIS & EURIBOR 6M
B2: NPV · DV01 · Duration · BPV · Carry · Greeks complets
B4: PARAMÈTRES SWAP | E4: TAUX DE MARCHÉ (from COURBE)
B5: Notionnel (M€) | C5: 100 | E5: €STR Bumped | F5: =IFERROR(VLOOKUP($C$12,COURBE!$B$8:$N$27,7,0),0) -> 0
B6: Maturité (ans) | C6: 10 | E6: E6M Bumped | F6: =IFERROR(VLOOKUP($C$12,COURBE!$B$8:$N$27,8,0),0) -> 0
B7: Taux Fixe (%) | C7: 2.52 | E7: DF (€STR) | F7: =IFERROR(VLOOKUP($C$12,COURBE!$B$8:$N$27,11,0),0) -> 0
B8: Fréquence (pmts/an) | C8: 1 | E8: Fwd €STR | F8: =IFERROR(VLOOKUP($C$12,COURBE!$B$8:$N$27,9,0),0) -> 0
B9: Direction | C9: PAY | E9: Taux Flottant | F9: =IF($C$10="ESTER",F5,F6)+$C$11/10000 -> 0
B10: Index | C10: ESTER | E10: Basis (pb) | F10: =IFERROR(VLOOKUP($C$12,COURBE!$B$8:$N$27,13,0),0) -> 0
B11: Spread Flottant(pb) | C11: 0
B12: Ref Courbe (tenor) | C12: 10
B14: MÉTRIQUES RISQUE
B15: DV01 (€/pb) | C15: =IF($C$9="PAY",-1,1)*$C$5*1000000*$C$6/10000 -> -100000
B16: BPV (€) | C16: =$C$5*1000000*($C$7/100)*$C$6/10000 -> 2520
B17: Duration modif. | C17: =IFERROR($C$6*(1+IF($C$10="ESTER",F5,F6))^(-1),0) -> 10
B18: Convexité | C18: =$C$6^2*(1+IF($C$10="ESTER",F5,F6))^(-2)*0.5 -> 50
B19: Theta/jour (€) | C19: =IF($C$9="PAY",-1,1)*$C$5*1000000*($C$7/100-F9)/365 -> -6904.1096
B20: Carry 3M (€) | C20: =IF($C$9="PAY",-1,1)*$C$5*1000000*($C$7/100-F9)*0.25 -> -630000
B21: NPV (€) | C21: =IF($C$9="PAY",-1,1)*$C$5*1000000*($C$7/100-IF($C$10="ESTER",F5,F6))*$C$6 -> -25200000
B22: VAR 99% 1J (€) | C22: =ABS(C15)*PARAMS!$C$5/10000 -> 600
B23: P&L +1pb | C23: =C15 -> -100000
B24: P&L -1pb | C24: =-C15 -> 100000
B25: P&L +25pb | C25: =C15*25 -> -2500000
B26: P&L -25pb | C26: =-C15*25 -> 2500000
B29: TABLEAU DE CASHFLOWS
B30: Période | C30: Temps(Y) | D30: CF Fixe(€) | E30: CF Flot(€) | F30: CF Net(€) | G30: DF | H30: PV(€) | I30: NPV Cum(€)
B31: 1 | C31: =IF(1>$C$6*$C$8,"",1/$C$8) -> 1 | D31: =IF(C31="","",IF($C$9="PAY",-1,1)*$C$5*1000000*($C$7/100)/$C$8) -> -2520000 | E31: =IF(C31="","",IF($C$9="PAY",1,-1)*$C$5*1000000*F9/$C$8) -> 0 | F31: =IF(C31="","",D31+E31) -> -2520000 | G31: =IF(C31="","",(1+IF($C$10="ESTER",F5,F6))^(-C31)) -> 1 | H31: =IF(C31="","",F31*G31) -> -2520000 | I31: =IF(C31="","",SUM($H$31:H31)) -> -2520000
B32: 2 | C32: =IF(2>$C$6*$C$8,"",2/$C$8) -> 2 | D32: =IF(C32="","",IF($C$9="PAY",-1,1)*$C$5*1000000*($C$7/100)/$C$8) -> -2520000 | E32: =IF(C32="","",IF($C$9="PAY",1,-1)*$C$5*1000000*F9/$C$8) -> 0 | F32: =IF(C32="","",D32+E32) -> -2520000 | G32: =IF(C32="","",(1+IF($C$10="ESTER",F5,F6))^(-C32)) -> 1 | H32: =IF(C32="","",F32*G32) -> -2520000 | I32: =IF(C32="","",SUM($H$31:H32)) -> -5040000
B33: 3 | C33: =IF(3>$C$6*$C$8,"",3/$C$8) -> 3 | D33: =IF(C33="","",IF($C$9="PAY",-1,1)*$C$5*1000000*($C$7/100)/$C$8) -> -2520000 | E33: =IF(C33="","",IF($C$9="PAY",1,-1)*$C$5*1000000*F9/$C$8) -> 0 | F33: =IF(C33="","",D33+E33) -> -2520000 | G33: =IF(C33="","",(1+IF($C$10="ESTER",F5,F6))^(-C33)) -> 1 | H33: =IF(C33="","",F33*G33) -> -2520000 | I33: =IF(C33="","",SUM($H$31:H33)) -> -7560000
B34: 4 | C34: =IF(4>$C$6*$C$8,"",4/$C$8) -> 4 | D34: =IF(C34="","",IF($C$9="PAY",-1,1)*$C$5*1000000*($C$7/100)/$C$8) -> -2520000 | E34: =IF(C34="","",IF($C$9="PAY",1,-1)*$C$5*1000000*F9/$C$8) -> 0 | F34: =IF(C34="","",D34+E34) -> -2520000 | G34: =IF(C34="","",(1+IF($C$10="ESTER",F5,F6))^(-C34)) -> 1 | H34: =IF(C34="","",F34*G34) -> -2520000 | I34: =IF(C34="","",SUM($H$31:H34)) -> -10080000
B35: 5 | C35: =IF(5>$C$6*$C$8,"",5/$C$8) -> 5 | D35: =IF(C35="","",IF($C$9="PAY",-1,1)*$C$5*1000000*($C$7/100)/$C$8) -> -2520000 | E35: =IF(C35="","",IF($C$9="PAY",1,-1)*$C$5*1000000*F9/$C$8) -> 0 | F35: =IF(C35="","",D35+E35) -> -2520000 | G35: =IF(C35="","",(1+IF($C$10="ESTER",F5,F6))^(-C35)) -> 1 | H35: =IF(C35="","",F35*G35) -> -2520000 | I35: =IF(C35="","",SUM($H$31:H35)) -> -12600000
B36: 6 | C36: =IF(6>$C$6*$C$8,"",6/$C$8) -> 6 | D36: =IF(C36="","",IF($C$9="PAY",-1,1)*$C$5*1000000*($C$7/100)/$C$8) -> -2520000 | E36: =IF(C36="","",IF($C$9="PAY",1,-1)*$C$5*1000000*F9/$C$8) -> 0 | F36: =IF(C36="","",D36+E36) -> -2520000 | G36: =IF(C36="","",(1+IF($C$10="ESTER",F5,F6))^(-C36)) -> 1 | H36: =IF(C36="","",F36*G36) -> -2520000 | I36: =IF(C36="","",SUM($H$31:H36)) -> -15120000
B37: 7 | C37: =IF(7>$C$6*$C$8,"",7/$C$8) -> 7 | D37: =IF(C37="","",IF($C$9="PAY",-1,1)*$C$5*1000000*($C$7/100)/$C$8) -> -2520000 | E37: =IF(C37="","",IF($C$9="PAY",1,-1)*$C$5*1000000*F9/$C$8) -> 0 | F37: =IF(C37="","",D37+E37) -> -2520000 | G37: =IF(C37="","",(1+IF($C$10="ESTER",F5,F6))^(-C37)) -> 1 | H37: =IF(C37="","",F37*G37) -> -2520000 | I37: =IF(C37="","",SUM($H$31:H37)) -> -17640000
B38: 8 | C38: =IF(8>$C$6*$C$8,"",8/$C$8) -> 8 | D38: =IF(C38="","",IF($C$9="PAY",-1,1)*$C$5*1000000*($C$7/100)/$C$8) -> -2520000 | E38: =IF(C38="","",IF($C$9="PAY",1,-1)*$C$5*1000000*F9/$C$8) -> 0 | F38: =IF(C38="","",D38+E38) -> -2520000 | G38: =IF(C38="","",(1+IF($C$10="ESTER",F5,F6))^(-C38)) -> 1 | H38: =IF(C38="","",F38*G38) -> -2520000 | I38: =IF(C38="","",SUM($H$31:H38)) -> -20160000
B39: 9 | C39: =IF(9>$C$6*$C$8,"",9/$C$8) -> 9 | D39: =IF(C39="","",IF($C$9="PAY",-1,1)*$C$5*1000000*($C$7/100)/$C$8) -> -2520000 | E39: =IF(C39="","",IF($C$9="PAY",1,-1)*$C$5*1000000*F9/$C$8) -> 0 | F39: =IF(C39="","",D39+E39) -> -2520000 | G39: =IF(C39="","",(1+IF($C$10="ESTER",F5,F6))^(-C39)) -> 1 | H39: =IF(C39="","",F39*G39) -> -2520000 | I39: =IF(C39="","",SUM($H$31:H39)) -> -22680000
B40: 10 | C40: =IF(10>$C$6*$C$8,"",10/$C$8) -> 10 | D40: =IF(C40="","",IF($C$9="PAY",-1,1)*$C$5*1000000*($C$7/100)/$C$8) -> -2520000 | E40: =IF(C40="","",IF($C$9="PAY",1,-1)*$C$5*1000000*F9/$C$8) -> 0 | F40: =IF(C40="","",D40+E40) -> -2520000 | G40: =IF(C40="","",(1+IF($C$10="ESTER",F5,F6))^(-C40)) -> 1 | H40: =IF(C40="","",F40*G40) -> -2520000 | I40: =IF(C40="","",SUM($H$31:H40)) -> -25200000
B41: 11 | C41: =IF(11>$C$6*$C$8,"",11/$C$8) | D41: =IF(C41="","",IF($C$9="PAY",-1,1)*$C$5*1000000*($C$7/100)/$C$8) | E41: =IF(C41="","",IF($C$9="PAY",1,-1)*$C$5*1000000*F9/$C$8) | F41: =IF(C41="","",D41+E41) | G41: =IF(C41="","",(1+IF($C$10="ESTER",F5,F6))^(-C41)) | H41: =IF(C41="","",F41*G41) | I41: =IF(C41="","",SUM($H$31:H41))
B42: 12 | C42: =IF(12>$C$6*$C$8,"",12/$C$8) | D42: =IF(C42="","",IF($C$9="PAY",-1,1)*$C$5*1000000*($C$7/100)/$C$8) | E42: =IF(C42="","",IF($C$9="PAY",1,-1)*$C$5*1000000*F9/$C$8) | F42: =IF(C42="","",D42+E42) | G42: =IF(C42="","",(1+IF($C$10="ESTER",F5,F6))^(-C42)) | H42: =IF(C42="","",F42*G42) | I42: =IF(C42="","",SUM($H$31:H42))
B43: 13 | C43: =IF(13>$C$6*$C$8,"",13/$C$8) | D43: =IF(C43="","",IF($C$9="PAY",-1,1)*$C$5*1000000*($C$7/100)/$C$8) | E43: =IF(C43="","",IF($C$9="PAY",1,-1)*$C$5*1000000*F9/$C$8) | F43: =IF(C43="","",D43+E43) | G43: =IF(C43="","",(1+IF($C$10="ESTER",F5,F6))^(-C43)) | H43: =IF(C43="","",F43*G43) | I43: =IF(C43="","",SUM($H$31:H43))
B44: 14 | C44: =IF(14>$C$6*$C$8,"",14/$C$8) | D44: =IF(C44="","",IF($C$9="PAY",-1,1)*$C$5*1000000*($C$7/100)/$C$8) | E44: =IF(C44="","",IF($C$9="PAY",1,-1)*$C$5*1000000*F9/$C$8) | F44: =IF(C44="","",D44+E44) | G44: =IF(C44="","",(1+IF($C$10="ESTER",F5,F6))^(-C44)) | H44: =IF(C44="","",F44*G44) | I44: =IF(C44="","",SUM($H$31:H44))
...

Sheet PCA RISK
B1: PROJECTION PCA DU RISQUE · 3 NIVEAUX DE LIQUIDITÉ
B2: ACP sur covariance historique EUR IRS | PC1=niveau PC2=pente PC3=courbure | 3 projections : ILLIQUIDE (3 piliers) · MOYEN (5) · LIQUIDE (7)
B4: ① PILIERS ILLIQUIDES [2Y · 10Y · 30Y]
B5: DV01 Projeté sur piliers (€/pb) — from BOOK:
C6: 2Y | D6: 10Y | E6: 30Y | F6: DV01 TOTAL
B7: DV01 net agrégé | C7: =IFERROR(SUMPRODUCT((BOOK!H8:H107=2)*BOOK!Q8:Q107),0) -> 0 | D7: =IFERROR(SUMPRODUCT((BOOK!H8:H107=10)*BOOK!Q8:Q107),0) -> 0 | E7: =IFERROR(SUMPRODUCT((BOOK!H8:H107=30)*BOOK!Q8:Q107),0) -> 0 | F7: =SUM(C7,D7,E7) -> 0
B9: Matrice de Covariance (pb²/an):
C10: 2Y | D10: 10Y | E10: 30Y
B11: 2Y | C11: 5487.2 | D11: 2284.2 | E11: 307.5
B12: 10Y | C12: 2284.2 | D12: 3420 | E12: 460.3
B13: 30Y | C13: 307.5 | D13: 460.3 | E13: 1520
B14: Valeurs propres (eigenvalues) & variance expliquée:
C15: PC1 | D15: PC2 | E15: PC3 | F15: Résiduel
B16: Eigenvalue (pb²) | C16: 7007.9 | D16: 2032.2 | E16: 1387.1
B17: % Variance expl. | C17: 0.6721 | D17: 0.1949 | E17: 0.133
B18: Cum. Variance | C18: 67.2 | D18: 86.7 | E18: 100 | F18: 0
B19: Volatilité (pb/√an) | C19: 83.7 | D19: 45.1 | E19: 37.2
B21: Vecteurs propres — Factor Loadings:
C22: PC1 Niveau | D22: PC2 Pente | E22: PC3 Courb.
B23: 2Y loading | C23: -0.8345 | D23: -0.5361 | E23: 0.1268
B24: 10Y loading | C24: -0.5432 | D24: 0.7621 | E24: -0.3525
B25: 30Y loading | C25: -0.0923 | D25: 0.363 | E25: 0.9272
B27: PROJECTION RISQUE SUR PCs (€/pb):
C28: PC1 | D28: PC2 | E28: PC3 | F28: Risque Total €
B29: DV01 projeté (€) | C29: =IFERROR(C7*-0.834542+D7*-0.543156+E7*-0.092314,0) -> 0 | D29: =IFERROR(C7*-0.536147+D7*0.762072+E7*0.363032,0) -> 0 | E29: =IFERROR(C7*0.126833+D7*-0.352459+E7*0.927193,0) -> 0 | F29: =IFERROR(SQRT(SUMPRODUCT((C29~D29~E29)^2)),0) -> 0
B30: Vol annuelle (pb×DV01) | C30: =IFERROR(ABS(C29)*83.7131,0) -> 0 | D30: =IFERROR(ABS(D29)*45.0804,0) -> 0 | E30: =IFERROR(ABS(E29)*37.2434,0) -> 0
B34: ② PILIERS INTERMÉDIAIRES [2Y·5Y·10Y·20Y·30Y]
B35: DV01 Projeté sur piliers (€/pb) — from BOOK:
C36: 2Y | D36: 5Y | E36: 10Y | F36: 20Y | G36: 30Y | H36: DV01 TOTAL
B37: DV01 net agrégé | C37: =IFERROR(SUMPRODUCT((BOOK!H8:H107=2)*BOOK!Q8:Q107),0) -> 0 | D37: =IFERROR(SUMPRODUCT((BOOK!H8:H107=5)*BOOK!Q8:Q107),0) -> 0 | E37: =IFERROR(SUMPRODUCT((BOOK!H8:H107=10)*BOOK!Q8:Q107),0) -> 0 | F37: =IFERROR(SUMPRODUCT((BOOK!H8:H107=20)*BOOK!Q8:Q107),0) -> 0 | G37: =IFERROR(SUMPRODUCT((BOOK!H8:H107=30)*BOOK!Q8:Q107),0) -> 0 | H37: =SUM(C37,D37,E37,F37,G37) -> 0
B39: Matrice de Covariance (pb²/an):
C40: 2Y | D40: 5Y | E40: 10Y | F40: 20Y | G40: 30Y
B41: 2Y | C41: 5487.2 | D41: 3975.6 | E41: 2284.2 | F41: 684.2 | G41: 307.5
B42: 5Y | C42: 3975.6 | D42: 4655 | E42: 2674.6 | F42: 801.2 | G42: 360
B43: 10Y | C43: 2284.2 | D43: 2674.6 | E43: 3420 | F43: 1024.5 | G43: 460.3
B44: 20Y | C44: 684.2 | D44: 801.2 | E44: 1024.5 | F44: 1520 | G44: 683
B45: 30Y | C45: 307.5 | D45: 360 | E45: 460.3 | F45: 683 | G45: 1520
B46: Valeurs propres (eigenvalues) & variance expliquée:
C47: PC1 | D47: PC2 | E47: PC3 | F47: PC4 | G47: PC5 | H47: Résiduel
B48: Eigenvalue (pb²) | C48: 10995.1 | D48: 2448.2 | E48: 1535.8 | F48: 887.8 | G48: 735.3
...

Sheet PCA MATRICES
A1: ▸ MATRICES PCA — ANALYSE EN COMPOSANTES PRINCIPALES DES TAUX IRS EURO
A2: Covariance · Corrélation · Eigenvalues · Eigenvectors · Projections DV01 × 3 niveaux de liquidité | ILLIQUIDE [2Y·10Y·30Y] · INTERMÉDIAIRE [2Y·5Y·10Y·20Y·30Y] · LIQUIDE [1Y·2Y·5Y·10Y·20Y·30Y·50Y]
B3: ← DASHBOARD | D3: ← COURBE | F3: ← BOOK | H3: ← PCA RISK | K3: ILLIQUIDES ↓ | M3: INTERMÉDIAIRES ↓ | O3: LIQUIDES ↓ | Q3: SYNTHÈSE ↓
A5: ① PILIERS ILLIQUIDES · Piliers : 2Y · 10Y · 30Y
B6: Nbre de piliers : 3 | D6: PC1 λ = 7008 pb² | F6: PC2 λ = 2032 pb² | H6: PC1+2+3 = 100.0% variance | K6: σ(PC1) = 83.7 pb/√an | M6: σ(PC2) = 45.1 pb/√an | O6: σ(PC3) = 37.2 pb/√an | P6: DV01 Book (€) → | Q6: =IFERROR(IFERROR(SUMPRODUCT((BOOK!H8:H107=2)*BOOK!Q8:Q107),0)+IFERROR(SUMPRODUCT((BOOK!H8:H107=10)*BOOK!Q8:Q107),0)+IFERROR(SUMPRODUCT((BOOK!H8:H107=30)*BOOK!Q8:Q107),0),0) -> 0
B8: MATRICE DE COVARIANCE Σ (pb²/an) | K8: MATRICE DES VECTEURS PROPRES (Loadings) V = [v₁|v₂|…|vₙ]
B9: Σ | C9: 2Y | D9: 10Y | E9: 30Y | K9: Tenor \ PC | L9: PC1 Niveau | M9: PC2 Pente | N9: PC3 Courb. | O9: σ(PC) pb/√an
B10: 2Y | C10: 5487.2 | D10: 2284.2 | E10: 307.5 | K10: 2Y | L10: -0.8345 | M10: -0.5361 | N10: 0.1268 | O10: 74.1
B11: 10Y | C11: 2284.2 | D11: 3420 | E11: 460.3 | K11: 10Y | L11: -0.5432 | M11: 0.7621 | N11: -0.3525 | O11: 58.5
B12: 30Y | C12: 307.5 | D12: 460.3 | E12: 1520 | K12: 30Y | L12: -0.0923 | M12: 0.363 | N12: 0.9272 | O12: 39
B13: σ (pb/√an) | C13: 74.1 | D13: 58.5 | E13: 39 | K13: −1.0 (négatif) | O13: +1.0 (positif)
B15: MATRICE DE CORRÉLATION ρ [−1 → +1] | K15: DÉCOMPOSITION SPECTRALE (Eigenvalues & Variance Expliquée)
B16: ρ | C16: 2Y | D16: 10Y | E16: 30Y | K16: Métrique | L16: PC1 | M16: PC2 | N16: PC3 | O16: TOTAL
B17: 2Y | C17: 1 | D17: 0.5273 | E17: 0.1065 | K17: λ (eigenvalue, pb²) | L17: 7007.9 | M17: 2032.2 | N17: 1387.1 | O17: 10427.2
B18: 10Y | C18: 0.5273 | D18: 1 | E18: 0.2019 | K18: √λ = σ (pb/√an) | L18: 83.71 | M18: 45.08 | N18: 37.24
B19: 30Y | C19: 0.1065 | D19: 0.2019 | E19: 1 | K19: % variance expliquée | L19: 0.6721 | M19: 0.1949 | N19: 0.133 | O19: 1
B20: −1.0 (corrélation négative) | F20: +1.0 (corrélation positive) | K20: % variance cumulée | L20: 0.6721 | M20: 0.867 | N20: 1 | O20: 1
K21: Contrib. risque (pb) | L21: 83.7 | M21: 45.1 | N21: 37.2
A23: PROJECTION DU DV01 BOOK SUR LES COMPOSANTES PRINCIPALES (PILIERS ILLIQUIDES)
B24: DV01 piliers ↓ | C24: DV01 2Y (€) | D24: DV01 10Y (€) | E24: DV01 30Y (€) | F24: DV01 TOTAL (€) | H24: Nota
B25: DV01 net agrégé du book | C25: =IFERROR(SUMPRODUCT((BOOK!H8:H107=2)*BOOK!Q8:Q107),0) -> 0 | D25: =IFERROR(SUMPRODUCT((BOOK!H8:H107=10)*BOOK!Q8:Q107),0) -> 0 | E25: =IFERROR(SUMPRODUCT((BOOK!H8:H107=30)*BOOK!Q8:Q107),0) -> 0 | F25: =SUM(C25,D25,E25) -> 0 | H25: Lié au BOOK — mise à jour automatique
B27: Composante | C27: Interprétation | D27: Loading (w·DV01/DV01 tot) | E27: DV01 projeté sur PC (€) | F27: σ(PC) pb/√an | G27: Risque annuel (€) | H27: % du risque total | I27: VAR 99% 1J (€) | K27: Commentaire
B28: PC1 PC1 Niveau | C28: Niveau (shift parallèle) | D28: 0.49 | E28: =IFERROR(C25*-0.834542 + D25*-0.543156 + E25*-0.092314, 0) -> 0 | F28: 83.71 | G28: =IFERROR(ABS(E28)*83.7131,0) -> 0 | H28: =IFERROR(G28/MAX(SUM(G28,G29,G30),1),0) -> 0 | I28: =IFERROR(ABS(E28)*83.7131/SQRT(252)*2.326,0) -> 0 | K28: Risque directionnel majeur — position nette courbe
B29: PC2 PC2 Pente | C29: Pente (steepening/flattening) | D29: 0.1963 | E29: =IFERROR(C25*-0.536147 + D25*0.762072 + E25*0.363032, 0) -> 0 | F29: 45.08 | G29: =IFERROR(ABS(E29)*45.0804,0) -> 0 | H29: =IFERROR(G29/MAX(SUM(G28,G29,G30),1),0) -> 0 | I29: =IFERROR(ABS(E29)*45.0804/SQRT(252)*2.326,0) -> 0 | K29: Risque de pentification/aplatissement
B30: PC3 PC3 Courb. | C30: Courbure (butterfly) | D30: 0.2339 | E30: =IFERROR(C25*0.126833 + D25*-0.352459 + E25*0.927193, 0) -> 0 | F30: 37.24 | G30: =IFERROR(ABS(E30)*37.2434,0) -> 0 | H30: =IFERROR(G30/MAX(SUM(G28,G29,G30),1),0) -> 0 | I30: =IFERROR(ABS(E30)*37.2434/SQRT(252)*2.326,0) -> 0 | K30: Risque de convexité — butterfly implicite
B31: RISQUE TOTAL PORTEFEUILLE (norme vectorielle) | E31: =IFERROR(SQRT(SUMPRODUCT((E28~E29~E30)^2)),0) -> 0 | G31: =IFERROR(SQRT(SUMPRODUCT((G28~G29~G30)^2)),0) -> 0 | I31: =IFERROR(G31/SQRT(252)*2.326,0) -> 0
A34: ② PILIERS INTERMÉDIAIRES · Piliers : 2Y · 5Y · 10Y · 20Y · 30Y
B35: Nbre de piliers : 5 | D35: PC1 λ = 10995 pb² | F35: PC2 λ = 2448 pb² | H35: PC1+2+3 = 90.2% variance | K35: σ(PC1) = 104.9 pb/√an | M35: σ(PC2) = 49.5 pb/√an | O35: σ(PC3) = 39.2 pb/√an | P35: DV01 Book (€) → | Q35: =IFERROR(IFERROR(SUMPRODUCT((BOOK!H8:H107=2)*BOOK!Q8:Q107),0)+IFERROR(SUMPRODUCT((BOOK!H8:H107=5)*BOOK!Q8:Q107),0)+IFERROR(SUMPRODUCT((BOOK!H8:H107=10)*BOOK!Q8:Q107),0)+IFERROR(SUMPRODUCT((BOOK!H8:H107=20)*BOOK!Q8:Q107),0)+IFERROR(SUMPRODUCT((BOOK!H8:H107=30)*BOOK!Q8:Q107),0),0) -> 0
B37: MATRICE DE COVARIANCE Σ (pb²/an) | K37: MATRICE DES VECTEURS PROPRES (Loadings) V = [v₁|v₂|…|vₙ]
B38: Σ | C38: 2Y | D38: 5Y | E38: 10Y | F38: 20Y | G38: 30Y | K38: Tenor \ PC | L38: PC1 Niveau | M38: PC2 Pente | N38: PC3 Courb. | O38: PC4 Twist | P38: PC5 | Q38: σ(PC) pb/√an
B39: 2Y | C39: 5487.2 | D39: 3975.6 | E39: 2284.2 | F39: 684.2 | G39: 307.5 | K39: 2Y | L39: -0.6424 | M39: -0.464 | N39: -0.3821 | O39: 0.4623 | P39: 0.1111 | Q39: 74.1
B40: 5Y | C40: 3975.6 | D40: 4655 | E40: 2674.6 | F40: 801.2 | G40: 360 | K40: 5Y | L40: -0.6091 | M40: -0.0791 | N40: 0.162 | O40: -0.7342 | P40: -0.2399 | Q40: 68.2
B41: 10Y | C41: 2284.2 | D41: 2674.6 | E41: 3420 | F41: 1024.5 | G41: 460.3 | K41: 10Y | L41: -0.4337 | M41: 0.5353 | N41: 0.5579 | O41: 0.3141 | P41: 0.3398 | Q41: 58.5
B42: 20Y | C42: 684.2 | D42: 801.2 | E42: 1024.5 | F42: 1520 | G42: 683 | K42: 20Y | L42: -0.1502 | M42: 0.5237 | N42: -0.3044 | O42: 0.2436 | P42: -0.7424 | Q42: 39
B43: 30Y | C43: 307.5 | D43: 360 | E43: 460.3 | F43: 683 | G43: 1520 | K43: 30Y | L43: -0.0759 | M43: 0.4665 | N43: -0.6511 | O43: -0.2987 | P43: 0.5134 | Q43: 39
B44: σ (pb/√an) | C44: 74.1 | D44: 68.2 | E44: 58.5 | F44: 39 | G44: 39 | K44: −1.0 (négatif) | Q44: +1.0 (positif)
B46: MATRICE DE CORRÉLATION ρ [−1 → +1] | K46: DÉCOMPOSITION SPECTRALE (Eigenvalues & Variance Expliquée)
B47: ρ | C47: 2Y | D47: 5Y | E47: 10Y | F47: 20Y | G47: 30Y | K47: Métrique | L47: PC1 | M47: PC2 | N47: PC3 | O47: PC4 | P47: PC5 | Q47: TOTAL
B48: 2Y | C48: 1 | D48: 0.7866 | E48: 0.5273 | F48: 0.2369 | G48: 0.1065 | K48: λ (eigenvalue, pb²) | L48: 10995.1 | M48: 2448.2 | N48: 1535.8 | O48: 887.8 | P48: 735.3 | Q48: 16602.2
B49: 5Y | C49: 0.7866 | D49: 1 | E49: 0.6703 | F49: 0.3012 | G49: 0.1353 | K49: √λ = σ (pb/√an) | L49: 104.86 | M49: 49.48 | N49: 39.19 | O49: 29.8 | P49: 27.12
...

Sheet FUTURES
A1: FUTURES EURO · EURIBOR 3M · BUND / BOBL / SCHATZ / BUXL / BTP / OAT
A2: Référentiel contrats | Book positions | DV01 | P&L | Implicite de taux | Packs & Bundles | Bleu = saisie
A4: EURIBOR 3M — CONTRATS DE RÉFÉRENCE (12 échéances) | K4: PACKS & BUNDLES EURIBOR 3M
B5: Contrat | C5: Échéance | D5: Taux impl.% | E5: Prix | F5: Var/veille | G5: OI (lots) | H5: DV01/lot | I5: Vol 1J(pb) | K5: Pack/Bundle | L5: Contracts | M5: Taux moy.% | N5: Nbre lots | O5: DV01 tot(€) | P5: P&L/pb(€) | Q5: Equiv. IRS
B6: ERH5 | C6: Mar-25 | D6: 3.45 | E6: =100-D6 -> 96.55 | F6: 0 | G6: 125000 | H6: 25 | I6: 2.5 | K6: Pack 2025 | L6: ERH5, ERM5, ERU5, ERZ5 | M6: 3.125 | N6: 0 | O6: =N6*4*25 -> 0 | P6: =N6*4*25/100 -> 0 | Q6: 1Y equiv
B7: ERM5 | C7: Jun-25 | D7: 3.2 | E7: =100-D7 -> 96.8 | F7: 0 | G7: 118000 | H7: 25 | I7: 2.5 | K7: Pack 2026 | L7: ERH6, ERM6, ERU6, ERZ6 | M7: 2.633 | N7: 0 | O7: =N7*4*25 -> 0 | P7: =N7*4*25/100 -> 0 | Q7: 2nd year
B8: ERU5 | C8: Sep-25 | D8: 3 | E8: =100-D8 -> 97 | F8: 0 | G8: 108000 | H8: 25 | I8: 2.5 | K8: Pack 2027 | L8: ERH7, ERM7, ERU7, ERZ7 | M8: 2.518 | N8: 0 | O8: =N8*4*25 -> 0 | P8: =N8*4*25/100 -> 0 | Q8: 3rd year
B9: ERZ5 | C9: Dec-25 | D9: 2.85 | E9: =100-D9 -> 97.15 | F9: 0 | G9: 95000 | H9: 25 | I9: 2.5 | K9: Bundle 2Y | L9: ERH5, ERM5, ERU5, ERZ5+4 | M9: 2.878 | N9: 0 | O9: =N9*8*25 -> 0 | P9: =N9*8*25/100 -> 0 | Q9: 2Y bundle
B10: ERH6 | C10: Mar-26 | D10: 2.72 | E10: =100-D10 -> 97.28 | F10: 0 | G10: 82000 | H10: 25 | I10: 2.5 | K10: Bundle 3Y | L10: ERH5, ERM5, ERU5, ERZ5+8 | M10: 2.762 | N10: 0 | O10: =N10*12*25 -> 0 | P10: =N10*12*25/100 -> 0 | Q10: 3Y bundle
B11: ERM6 | C11: Jun-26 | D11: 2.65 | E11: =100-D11 -> 97.35 | F11: 0 | G11: 71000 | H11: 25 | I11: 2.5
B12: ERU6 | C12: Sep-26 | D12: 2.6 | E12: =100-D12 -> 97.4 | F12: 0 | G12: 58000 | H12: 25 | I12: 2.5
B13: ERZ6 | C13: Dec-26 | D13: 2.56 | E13: =100-D13 -> 97.44 | F13: 0 | G13: 45000 | H13: 25 | I13: 2.5
B14: ERH7 | C14: Mar-27 | D14: 2.53 | E14: =100-D14 -> 97.47 | F14: 0 | G14: 35000 | H14: 25 | I14: 2.5
B15: ERM7 | C15: Jun-27 | D15: 2.52 | E15: =100-D15 -> 97.48 | F15: 0 | G15: 28000 | H15: 25 | I15: 2.5
B16: ERU7 | C16: Sep-27 | D16: 2.51 | E16: =100-D16 -> 97.49 | F16: 0 | G16: 22000 | H16: 25 | I16: 2.5
B17: ERZ7 | C17: Dec-27 | D17: 2.51 | E17: =100-D17 -> 97.49 | F17: 0 | G17: 18000 | H17: 25 | I17: 2.5
A19: FUTURES OBLIGATAIRES — EUREX (Bund · Bobl · Schatz · Buxl · BTP · OAT)
B20: Ticker | C20: Contrat | D20: Échéance | E20: Prix | F20: Durée CTD | G20: DV01/lot(€) | H20: Coupon CTD | I20: Yield CTD
B21: GBX | C21: BUXL 30Y | D21: Mar-25 | E21: 128.5 | F21: 20.5 | G21: =ROUND(F21*100000*0.0001,2) -> 205 | H21: 0.0125 | I21: 0.0245
B22: GBL | C22: BUND 10Y | D22: Mar-25 | E22: 134.2 | F22: 8.8 | G22: =ROUND(F22*100000*0.0001,2) -> 88 | H22: 0.02 | I22: 0.0252
B23: GBM | C23: BOBL 5Y | D23: Mar-25 | E23: 118.4 | F23: 4.6 | G23: =ROUND(F23*100000*0.0001,2) -> 46 | H23: 0.01 | I23: 0.0268
B24: GBS | C24: SCHATZ 2Y | D24: Mar-25 | E24: 107.8 | F24: 1.9 | G24: =ROUND(F24*100000*0.0001,2) -> 19 | H24: 0.025 | I24: 0.032
B25: IGB | C25: BTP 10Y | D25: Mar-25 | E25: 119.6 | F25: 8.2 | G25: =ROUND(F25*100000*0.0001,2) -> 82 | H25: 0.03 | I25: 0.0345
B26: OAT | C26: OAT 10Y | D26: Mar-25 | E26: 130.2 | F26: 8.6 | G26: =ROUND(F26*100000*0.0001,2) -> 86 | H26: 0.015 | I26: 0.0275
A29: BOOK DE POSITIONS FUTURES (50 slots | colonnes bleues = saisie)
A30: # | B30: Trade ID | C30: Contrat | D30: Type | E30: Dir. | F30: Nb lots | G30: Prix achat | H30: Prix actuel | I30: Var(%) | J30: DV01/lot(€) | K30: DV01 net(€) | L30: Gamma(€/pb²) | M30: Carry/j(€) | N30: P&L Jour(€) | O30: P&L Total(€) | P30: Greeks | Q30: Commentaire
A31: 1 | B31: FT-001 | C31: ERZ5 | D31: ER3M | E31: LONG | F31: 10 | G31: 97.15 | H31: 97.15 | I31: =IF(G31="","",IFERROR((H31-G31)/G31*100,0)) -> 0 | J31: =IF(C31="","",IFERROR(IF(D31="ER3M",25,INDEX(FUTURES!$G$21:$G$26,MATCH(C31,FUTURES!$B$21:$B$26,0))),25)) -> 25 | K31: =IF(J31="","",IF(E31="LONG",1,-1)*F31*J31) -> 250 | L31: =IF(D31="BOND",IFERROR(F31*J31*0.5,0),0) -> 0 | M31: =IF(C31="","",IF(D31="ER3M",IF(E31="LONG",1,-1)*F31*(100-H31)/100/360*1000000/100,IF(E31="LONG",1,-1)*F31*0.02/365*100000)) -> 7.9166667 | N31: =IF(J31="","",IF(E31="LONG",1,-1)*F31*J31*I31/100*100) -> 0 | O31: =IF(G31="","",IF(E31="LONG",1,-1)*F31*(H31-G31)*IF(D31="ER3M",2500,1000)) -> 0
A32: 2 | B32: FT-002 | C32: GBL | D32: BOND | E32: SHORT | F32: 5 | G32: 134.2 | H32: 134.2 | I32: =IF(G32="","",IFERROR((H32-G32)/G32*100,0)) -> 0 | J32: =IF(C32="","",IFERROR(IF(D32="ER3M",25,INDEX(FUTURES!$G$21:$G$26,MATCH(C32,FUTURES!$B$21:$B$26,0))),25)) -> 88 | K32: =IF(J32="","",IF(E32="LONG",1,-1)*F32*J32) -> -440 | L32: =IF(D32="BOND",IFERROR(F32*J32*0.5,0),0) -> 220 | M32: =IF(C32="","",IF(D32="ER3M",IF(E32="LONG",1,-1)*F32*(100-H32)/100/360*1000000/100,IF(E32="LONG",1,-1)*F32*0.02/365*100000)) -> -27.39726 | N32: =IF(J32="","",IF(E32="LONG",1,-1)*F32*J32*I32/100*100) -> 0 | O32: =IF(G32="","",IF(E32="LONG",1,-1)*F32*(H32-G32)*IF(D32="ER3M",2500,1000)) -> 0
A33: 3 | B33: FT-003 | C33: ERH6 | D33: ER3M | E33: LONG | F33: 20 | G33: 97.28 | H33: 97.28 | I33: =IF(G33="","",IFERROR((H33-G33)/G33*100,0)) -> 0 | J33: =IF(C33="","",IFERROR(IF(D33="ER3M",25,INDEX(FUTURES!$G$21:$G$26,MATCH(C33,FUTURES!$B$21:$B$26,0))),25)) -> 25 | K33: =IF(J33="","",IF(E33="LONG",1,-1)*F33*J33) -> 500 | L33: =IF(D33="BOND",IFERROR(F33*J33*0.5,0),0) -> 0 | M33: =IF(C33="","",IF(D33="ER3M",IF(E33="LONG",1,-1)*F33*(100-H33)/100/360*1000000/100,IF(E33="LONG",1,-1)*F33*0.02/365*100000)) -> 15.111111 | N33: =IF(J33="","",IF(E33="LONG",1,-1)*F33*J33*I33/100*100) -> 0 | O33: =IF(G33="","",IF(E33="LONG",1,-1)*F33*(H33-G33)*IF(D33="ER3M",2500,1000)) -> 0
A34: 4 | I34: =IF(G34="","",IFERROR((H34-G34)/G34*100,0)) | J34: =IF(C34="","",IFERROR(IF(D34="ER3M",25,INDEX(FUTURES!$G$21:$G$26,MATCH(C34,FUTURES!$B$21:$B$26,0))),25)) | K34: =IF(J34="","",IF(E34="LONG",1,-1)*F34*J34) | L34: =IF(D34="BOND",IFERROR(F34*J34*0.5,0),0) -> 0 | M34: =IF(C34="","",IF(D34="ER3M",IF(E34="LONG",1,-1)*F34*(100-H34)/100/360*1000000/100,IF(E34="LONG",1,-1)*F34*0.02/365*100000)) | N34: =IF(J34="","",IF(E34="LONG",1,-1)*F34*J34*I34/100*100) | O34: =IF(G34="","",IF(E34="LONG",1,-1)*F34*(H34-G34)*IF(D34="ER3M",2500,1000))
A35: 5 | I35: =IF(G35="","",IFERROR((H35-G35)/G35*100,0)) | J35: =IF(C35="","",IFERROR(IF(D35="ER3M",25,INDEX(FUTURES!$G$21:$G$26,MATCH(C35,FUTURES!$B$21:$B$26,0))),25)) | K35: =IF(J35="","",IF(E35="LONG",1,-1)*F35*J35) | L35: =IF(D35="BOND",IFERROR(F35*J35*0.5,0),0) -> 0 | M35: =IF(C35="","",IF(D35="ER3M",IF(E35="LONG",1,-1)*F35*(100-H35)/100/360*1000000/100,IF(E35="LONG",1,-1)*F35*0.02/365*100000)) | N35: =IF(J35="","",IF(E35="LONG",1,-1)*F35*J35*I35/100*100) | O35: =IF(G35="","",IF(E35="LONG",1,-1)*F35*(H35-G35)*IF(D35="ER3M",2500,1000))
A36: 6 | I36: =IF(G36="","",IFERROR((H36-G36)/G36*100,0)) | J36: =IF(C36="","",IFERROR(IF(D36="ER3M",25,INDEX(FUTURES!$G$21:$G$26,MATCH(C36,FUTURES!$B$21:$B$26,0))),25)) | K36: =IF(J36="","",IF(E36="LONG",1,-1)*F36*J36) | L36: =IF(D36="BOND",IFERROR(F36*J36*0.5,0),0) -> 0 | M36: =IF(C36="","",IF(D36="ER3M",IF(E36="LONG",1,-1)*F36*(100-H36)/100/360*1000000/100,IF(E36="LONG",1,-1)*F36*0.02/365*100000)) | N36: =IF(J36="","",IF(E36="LONG",1,-1)*F36*J36*I36/100*100) | O36: =IF(G36="","",IF(E36="LONG",1,-1)*F36*(H36-G36)*IF(D36="ER3M",2500,1000))
A37: 7 | I37: =IF(G37="","",IFERROR((H37-G37)/G37*100,0)) | J37: =IF(C37="","",IFERROR(IF(D37="ER3M",25,INDEX(FUTURES!$G$21:$G$26,MATCH(C37,FUTURES!$B$21:$B$26,0))),25)) | K37: =IF(J37="","",IF(E37="LONG",1,-1)*F37*J37) | L37: =IF(D37="BOND",IFERROR(F37*J37*0.5,0),0) -> 0 | M37: =IF(C37="","",IF(D37="ER3M",IF(E37="LONG",1,-1)*F37*(100-H37)/100/360*1000000/100,IF(E37="LONG",1,-1)*F37*0.02/365*100000)) | N37: =IF(J37="","",IF(E37="LONG",1,-1)*F37*J37*I37/100*100) | O37: =IF(G37="","",IF(E37="LONG",1,-1)*F37*(H37-G37)*IF(D37="ER3M",2500,1000))
A38: 8 | I38: =IF(G38="","",IFERROR((H38-G38)/G38*100,0)) | J38: =IF(C38="","",IFERROR(IF(D38="ER3M",25,INDEX(FUTURES!$G$21:$G$26,MATCH(C38,FUTURES!$B$21:$B$26,0))),25)) | K38: =IF(J38="","",IF(E38="LONG",1,-1)*F38*J38) | L38: =IF(D38="BOND",IFERROR(F38*J38*0.5,0),0) -> 0 | M38: =IF(C38="","",IF(D38="ER3M",IF(E38="LONG",1,-1)*F38*(100-H38)/100/360*1000000/100,IF(E38="LONG",1,-1)*F38*0.02/365*100000)) | N38: =IF(J38="","",IF(E38="LONG",1,-1)*F38*J38*I38/100*100) | O38: =IF(G38="","",IF(E38="LONG",1,-1)*F38*(H38-G38)*IF(D38="ER3M",2500,1000))
A39: 9 | I39: =IF(G39="","",IFERROR((H39-G39)/G39*100,0)) | J39: =IF(C39="","",IFERROR(IF(D39="ER3M",25,INDEX(FUTURES!$G$21:$G$26,MATCH(C39,FUTURES!$B$21:$B$26,0))),25)) | K39: =IF(J39="","",IF(E39="LONG",1,-1)*F39*J39) | L39: =IF(D39="BOND",IFERROR(F39*J39*0.5,0),0) -> 0 | M39: =IF(C39="","",IF(D39="ER3M",IF(E39="LONG",1,-1)*F39*(100-H39)/100/360*1000000/100,IF(E39="LONG",1,-1)*F39*0.02/365*100000)) | N39: =IF(J39="","",IF(E39="LONG",1,-1)*F39*J39*I39/100*100) | O39: =IF(G39="","",IF(E39="LONG",1,-1)*F39*(H39-G39)*IF(D39="ER3M",2500,1000))
A40: 10 | I40: =IF(G40="","",IFERROR((H40-G40)/G40*100,0)) | J40: =IF(C40="","",IFERROR(IF(D40="ER3M",25,INDEX(FUTURES!$G$21:$G$26,MATCH(C40,FUTURES!$B$21:$B$26,0))),25)) | K40: =IF(J40="","",IF(E40="LONG",1,-1)*F40*J40) | L40: =IF(D40="BOND",IFERROR(F40*J40*0.5,0),0) -> 0 | M40: =IF(C40="","",IF(D40="ER3M",IF(E40="LONG",1,-1)*F40*(100-H40)/100/360*1000000/100,IF(E40="LONG",1,-1)*F40*0.02/365*100000)) | N40: =IF(J40="","",IF(E40="LONG",1,-1)*F40*J40*I40/100*100) | O40: =IF(G40="","",IF(E40="LONG",1,-1)*F40*(H40-G40)*IF(D40="ER3M",2500,1000))
A41: 11 | I41: =IF(G41="","",IFERROR((H41-G41)/G41*100,0)) | J41: =IF(C41="","",IFERROR(IF(D41="ER3M",25,INDEX(FUTURES!$G$21:$G$26,MATCH(C41,FUTURES!$B$21:$B$26,0))),25)) | K41: =IF(J41="","",IF(E41="LONG",1,-1)*F41*J41) | L41: =IF(D41="BOND",IFERROR(F41*J41*0.5,0),0) -> 0 | M41: =IF(C41="","",IF(D41="ER3M",IF(E41="LONG",1,-1)*F41*(100-H41)/100/360*1000000/100,IF(E41="LONG",1,-1)*F41*0.02/365*100000)) | N41: =IF(J41="","",IF(E41="LONG",1,-1)*F41*J41*I41/100*100) | O41: =IF(G41="","",IF(E41="LONG",1,-1)*F41*(H41-G41)*IF(D41="ER3M",2500,1000))
A42: 12 | I42: =IF(G42="","",IFERROR((H42-G42)/G42*100,0)) | J42: =IF(C42="","",IFERROR(IF(D42="ER3M",25,INDEX(FUTURES!$G$21:$G$26,MATCH(C42,FUTURES!$B$21:$B$26,0))),25)) | K42: =IF(J42="","",IF(E42="LONG",1,-1)*F42*J42) | L42: =IF(D42="BOND",IFERROR(F42*J42*0.5,0),0) -> 0 | M42: =IF(C42="","",IF(D42="ER3M",IF(E42="LONG",1,-1)*F42*(100-H42)/100/360*1000000/100,IF(E42="LONG",1,-1)*F42*0.02/365*100000)) | N42: =IF(J42="","",IF(E42="LONG",1,-1)*F42*J42*I42/100*100) | O42: =IF(G42="","",IF(E42="LONG",1,-1)*F42*(H42-G42)*IF(D42="ER3M",2500,1000))
A43: 13 | I43: =IF(G43="","",IFERROR((H43-G43)/G43*100,0)) | J43: =IF(C43="","",IFERROR(IF(D43="ER3M",25,INDEX(FUTURES!$G$21:$G$26,MATCH(C43,FUTURES!$B$21:$B$26,0))),25)) | K43: =IF(J43="","",IF(E43="LONG",1,-1)*F43*J43) | L43: =IF(D43="BOND",IFERROR(F43*J43*0.5,0),0) -> 0 | M43: =IF(C43="","",IF(D43="ER3M",IF(E43="LONG",1,-1)*F43*(100-H43)/100/360*1000000/100,IF(E43="LONG",1,-1)*F43*0.02/365*100000)) | N43: =IF(J43="","",IF(E43="LONG",1,-1)*F43*J43*I43/100*100) | O43: =IF(G43="","",IF(E43="LONG",1,-1)*F43*(H43-G43)*IF(D43="ER3M",2500,1000))
A44: 14 | I44: =IF(G44="","",IFERROR((H44-G44)/G44*100,0)) | J44: =IF(C44="","",IFERROR(IF(D44="ER3M",25,INDEX(FUTURES!$G$21:$G$26,MATCH(C44,FUTURES!$B$21:$B$26,0))),25)) | K44: =IF(J44="","",IF(E44="LONG",1,-1)*F44*J44) | L44: =IF(D44="BOND",IFERROR(F44*J44*0.5,0),0) -> 0 | M44: =IF(C44="","",IF(D44="ER3M",IF(E44="LONG",1,-1)*F44*(100-H44)/100/360*1000000/100,IF(E44="LONG",1,-1)*F44*0.02/365*100000)) | N44: =IF(J44="","",IF(E44="LONG",1,-1)*F44*J44*I44/100*100) | O44: =IF(G44="","",IF(E44="LONG",1,-1)*F44*(H44-G44)*IF(D44="ER3M",2500,1000))
...

Sheet STRATS FUTURES
A1: STRATÉGIES FUTURES · BOX · SNAKE · CALENDAR · TED · HEDGE IRS/FUT · CONDOR · BASIS
A2: Simulateur de stratégies sur futures Euro | Taux importés de FUTURES | P&L et DV01 nets calculés automatiquement
B4: ① CALENDAR SPREAD — Achat/vente de 2 échéances consécutives | N4: ② BOX SPREAD (4 pattes) — Court 1 spread + Long 1 spread décalé
B5: Paramètre | C5: Jambe Courte | D5: Jambe Longue | E5: Différence | F5: Unité | N5: Paramètre | O5: Leg1 (L-S) | P5: Leg2 (S-L) | Q5: Net Box | R5: Unité | S5: Commentaire
B6: Contrat | C6: ERM5 | D6: ERU5 | E6: Contrat N+1 - N | F6: - | N6: Contrat Leg1 (achat) | O6: ERH5 | P6: —
B7: Taux impl.% | C7: 3.2 | D7: 3 | E7: =(D7-C7)*100 -> -20 | F7: - | N7: Contrat Leg2 (vente) | O7: ERM5 | P7: —
B8: Prix | C8: 96.8 | D8: 97 | E8: =(D8-C8)*100 -> 20 | F8: - | N8: Contrat Leg3 (vente) | O8: ERM5 | P8: —
B9: Nb lots | C9: 10 | D9: 10 | E9: =0 -> 0 | F9: - | N9: Contrat Leg4 (achat) | O9: ERU5 | P9: —
B10: DV01/lot(€) | C10: 25 | D10: 25 | F10: - | N10: Nb lots | O10: 10
B11: DV01 net(€) | C11: ='STRATS FUTURES'!C9*25 -> 250 | D11: ='STRATS FUTURES'!D9*25 -> 250 | E11: =D11-C11 -> 0 | F11: - | N11: Spread 1-2 (pb) | O11: =IFERROR((FUTURES!D7-FUTURES!D6),0) -> -0.25 | P11: =IFERROR((FUTURES!D8-FUTURES!D7),0) -> -0.2
B12: P&L/pb(€) | C12: =C9*25 -> 250 | D12: =D9*25 -> 250 | E12: =D12-C12 -> 0 | F12: - | N12: Spread 3-4 (pb) | O12: =IFERROR(FUTURES!D8-FUTURES!D7,0) -> -0.2
B13: Carry/j(€) | C13: =0 -> 0 | D13: =0 -> 0 | E13: =C13+D13 -> 0 | F13: - | N13: Box Value (pb) | O13: =IFERROR(P11-P11,0) -> 0
B14: P&L +10pb court | C14: =0 -> 0 | D14: =0 -> 0 | E14: =C14+D14 -> 0 | F14: - | N14: DV01 net (€) | O14: =IFERROR(O10*25*2,0) -> 500
B15: P&L +10pb long | C15: =0 -> 0 | D15: =0 -> 0 | E15: =C15+D15 -> 0 | F15: - | N15: P&L Box /pb | O15: =IFERROR(O10*25*2,0) -> 500
B18: ③ SNAKE / STRIP — Position directionnelle sur N échéances consécutives | N18: ④ CONDOR — 4 échéances (sell 2 belly, buy 2 wings)
B19: Contrat | C19: Dir. | D19: Nb lots | E19: Taux% | F19: DV01(€) | G19: P&L/1pb(€) | H19: Carry/j(€) | N19: Position | O19: Contrat | P19: Lots | Q19: Taux% | R19: DV01(€) | S19: P&L/1pb(€) | T19: Commentaire
B20: ERM5 | C20: LONG | D20: 10 | E20: 3.2 | F20: =IF(C20="LONG",-1,1)*D20*25 -> -250 | G20: =IF(C20="LONG",-1,1)*D20*25 -> -250 | H20: =IF(C20="LONG",1,-1)*D20*E20/100/360*1000000/100 -> 8.8888889 | N20: BUY Wing1 | O20: ERH5 | P20: 10 | Q20: 3.45 | R20: =1*P20*25 -> 250 | S20: =1*P20*25 -> 250 | T20: Long vol
B21: ERU5 | C21: LONG | D21: 10 | E21: 3 | F21: =IF(C21="LONG",-1,1)*D21*25 -> -250 | G21: =IF(C21="LONG",-1,1)*D21*25 -> -250 | H21: =IF(C21="LONG",1,-1)*D21*E21/100/360*1000000/100 -> 8.3333333 | N21: SELL Body1 | O21: ERM5 | P21: 20 | Q21: 3.2 | R21: =-1*P21*25 -> -500 | S21: =-1*P21*25 -> -500 | T21: Short vol
B22: ERZ5 | C22: LONG | D22: 10 | E22: 2.85 | F22: =IF(C22="LONG",-1,1)*D22*25 -> -250 | G22: =IF(C22="LONG",-1,1)*D22*25 -> -250 | H22: =IF(C22="LONG",1,-1)*D22*E22/100/360*1000000/100 -> 7.9166667 | N22: SELL Body2 | O22: ERU5 | P22: 20 | Q22: 3 | R22: =-1*P22*25 -> -500 | S22: =-1*P22*25 -> -500 | T22: Short vol
